Workbook

Sheet ttk_dfs
A1: 序号 | B1: 武器列表 | D1: 单发伤害 | I1: 弹匣容量 | J1: 击杀需要的子弹数量 | N1: RPM | O1: TTK（全打胸，单位秒） | S1: DFS 第一秒内伤害 （全打胸） | T1: 备注
D2: 胸部 | E2: 腿部 | G2: 头部 | J2: 白甲 （150） | K2: 蓝甲 （175） | L2: 紫甲 （200） | M2: 红甲 （225） | O2: 白甲 （150） | P2: 蓝甲 （175） | Q2: 紫甲 （200） | R2: 红甲 （225）
E3: 伤害倍率 | F3: 具体数值 | G3: 伤害倍率 | H3: 具体数值 | J3: 150 | K3: 175 | L3: 200 | M3: 225 | O3: 150 | P3: 175 | Q3: 200 | R3: 225
A4: 1 | B4: 塞拉轻机枪 | D4: 14 | E4: 1 | F4: =FLOOR(D4*E4,1) -> 14 | G4: 2 | H4: =FLOOR(D4*G4,1) -> 28 | I4: 173 | J4: =CEILING(J$3/$D4,1) -> 11 | K4: =CEILING(K$3/$D4,1) -> 13 | L4: =CEILING(L$3/$D4,1) -> 15 | M4: =CEILING(M$3/$D4,1) -> 17 | N4: 1200 | O4: =(J4-1)*(60/$N4) -> 0.5 | P4: =(K4-1)*(60/$N4) -> 0.6 | Q4: =(L4-1)*(60/$N4) -> 0.7 | R4: =(M4-1)*(60/$N4) -> 0.8 | S4: =TRUNC($D4*($N4/60)) -> 280
A5: 2 | B5: 专注轻机枪 | C5: 有涡轮 | D5: 16 | E5: 0.9 | F5: =FLOOR(D5*E5,1) -> 14 | G5: 1.25 | H5: =FLOOR(D5*G5,1) -> 20 | I5: 36/40/44/48 | J5: =CEILING(J$3/$D5,1) -> 10 | K5: =CEILING(K$3/$D5,1) -> 11 | L5: =CEILING(L$3/$D5,1) -> 13 | M5: =CEILING(M$3/$D5,1) -> 15 | N5: 900 | O5: =(J5-1)*(60/$N5) -> 0.6 | P5: =(K5-1)*(60/$N5) -> 0.66666667 | Q5: =(L5-1)*(60/$N5) -> 0.8 | R5: =(M5-1)*(60/$N5) -> 0.93333333 | S5: =TRUNC($D5*($N5/60)) -> 240
C6: 无涡轮 | D6: 16 | E6: 0.9 | F6: =FLOOR(D6*E6,1) -> 14 | G6: 1.25 | H6: =FLOOR(D6*G6,1) -> 20 | J6: =CEILING(J$3/$D6,1) -> 10 | K6: =CEILING(K$3/$D6,1) -> 11 | L6: =CEILING(L$3/$D6,1) -> 13 | M6: =CEILING(M$3/$D6,1) -> 15 | N6: 300 | O6: =(J6-1)*(60/$N6) -> 1.8 | P6: =(K6-1)*(60/$N6) -> 2 | Q6: =(L6-1)*(60/$N6) -> 2.4 | R6: =(M6-1)*(60/$N6) -> 2.8 | S6: =TRUNC($D6*($N6/60)) -> 80
A7: 3 | B7: L-star | C7: 空投武器 | D7: 22 | E7: 0.8 | F7: =FLOOR(D7*E7,1) -> 17 | G7: 1.25 | H7: =FLOOR(D7*G7,1) -> 27 | I7: 28 | J7: =CEILING(J$3/$D7,1) -> 7 | K7: =CEILING(K$3/$D7,1) -> 8 | L7: =CEILING(L$3/$D7,1) -> 10 | M7: =CEILING(M$3/$D7,1) -> 11 | N7: 600 | O7: =(J7-1)*(60/$N7) -> 0.6 | P7: =(K7-1)*(60/$N7) -> 0.7 | Q7: =(L7-1)*(60/$N7) -> 0.9 | R7: =(M7-1)*(60/$N7) -> 1 | S7: =TRUNC($D7*($N7/60)) -> 220
A8: 4 | B8: 猎兽冲锋枪 | C8: 全自动 | D8: 17 | E8: 0.8 | F8: =FLOOR(D8*E8,1) -> 13 | G8: 1.2 | H8: =FLOOR(D8*G8,1) -> 20 | I8: 20/25/30/35 | J8: =CEILING(J$3/$D8,1) -> 9 | K8: =CEILING(K$3/$D8,1) -> 11 | L8: =CEILING(L$3/$D8,1) -> 12 | M8: =CEILING(M$3/$D8,1) -> 14 | N8: 800 | O8: =(J8-1)*(60/$N8) -> 0.6 | P8: =(K8-1)*(60/$N8) -> 0.75 | Q8: =(L8-1)*(60/$N8) -> 0.825 | R8: =(M8-1)*(60/$N8) -> 0.975 | S8: =TRUNC($D8*($N8/60)) -> 226
C9: 五连发 | D9: 16 | E9: 0.8 | F9: =FLOOR(D9*E9,1) -> 12 | G9: 1.2 | H9: =FLOOR(D9*G9,1) -> 19 | J9: =CEILING(J$3/$D9,1) -> 10 | K9: =CEILING(K$3/$D9,1) -> 11 | L9: =CEILING(L$3/$D9,1) -> 13 | M9: =CEILING(M$3/$D9,1) -> 15 | N9: 820 | O9: =(J9-1)*(60/$N9) -> 0.65853659 | P9: =(K9-1)*(60/$N9) -> 0.73170732 | Q9: =(L9-1)*(60/$N9) -> 0.87804878 | R9: =(M9-1)*(60/$N9) -> 1.0243902 | S9: =TRUNC($D9*($N9/60)) -> 218
A10: 5 | B10: 哈沃克 | D10: 20 | E10: 0.75 | F10: =FLOOR(D10*E10,1) -> 15 | G10: 1.25 | H10: =FLOOR(D10*G10,1) -> 25 | I10: 18/21/25/29 | J10: =CEILING(J$3/$D10,1) -> 8 | K10: =CEILING(K$3/$D10,1) -> 9 | L10: =CEILING(L$3/$D10,1) -> 10 | M10: =CEILING(M$3/$D10,1) -> 12 | N10: 672 | O10: =(J10-1)*(60/$N10) -> 0.625 | P10: =(K10-1)*(60/$N10) -> 0.71428571 | Q10: =(L10-1)*(60/$N10) -> 0.80357143 | R10: =(M10-1)*(60/$N10) -> 0.98214286 | S10: =TRUNC($D10*($N10/60)) -> 224
A11: 6 | B11: Eva-8 | C11: 紫枪栓 | D11: 56 | E11: 1 | F11: =FLOOR(D11*E11,1) -> 56 | G11: 1 | H11: =FLOOR(D11*G11,1) -> 56 | I11: 8 | J11: =CEILING(J$3/$D11,1) -> 3 | K11: =CEILING(K$3/$D11,1) -> 4 | L11: =CEILING(L$3/$D11,1) -> 4 | M11: =CEILING(M$3/$D11,1) -> 5 | N11: 200 | O11: =(J11-1)*(60/$N11) -> 0.6 | P11: =(K11-1)*(60/$N11) -> 0.9 | Q11: =(L11-1)*(60/$N11) -> 0.9 | R11: =(M11-1)*(60/$N11) -> 1.2 | S11: =TRUNC($D11*($N11/60)) -> 186 | T11: 此处RPM暴降是因为 双发只是射出2发的速度变短一些等效于这个RPM
C12: 紫枪栓+双发扳机 | D12: 102 | E12: 1 | F12: =FLOOR(D12*E12,1) -> 102 | G12: 1.25 | H12: =FLOOR(D12*G12,1) -> 127 | J12: =CEILING(J$3/$D12,1) -> 2 | K12: =CEILING(K$3/$D12,1) -> 2 | L12: =CEILING(L$3/$D12,1) -> 2 | M12: =CEILING(M$3/$D12,1) -> 3 | N12: 43 | O12: =(J12-1)*(60/$N12) -> 1.3953488 | P12: =(K12-1)*(60/$N12) -> 1.3953488 | Q12: =(L12-1)*(60/$N12) -> 1.3953488 | R12: =(M12-1)*(60/$N12) -> 2.7906977 | S12: =TRUNC($D12*($N12/60)) -> 73
A13: 7 | B13: 莫桑比克 | C13: 双持-紫枪栓 | D13: 51 | E13: 1 | F13: =FLOOR(D13*E13,1) -> 51 | G13: 1.25 | H13: =FLOOR(D13*G13,1) -> 63 | I13: 10 | J13: =CEILING(J$3/$D13,1) -> 3 | K13: =CEILING(K$3/$D13,1) -> 4 | L13: =CEILING(L$3/$D13,1) -> 4 | M13: =CEILING(M$3/$D13,1) -> 5 | N13: 210 | O13: =(J13-1)*(60/$N13) -> 0.57142857 | P13: =(K13-1)*(60/$N13) -> 0.85714286 | Q13: =(L13-1)*(60/$N13) -> 0.85714286 | R13: =(M13-1)*(60/$N13) -> 1.1428571 | S13: =TRUNC($D13*($N13/60)) -> 178
A14: 8 | B14: 复仇女神 | C14: 涡轮 | D14: 17 | E14: 0.75 | F14: =FLOOR(D14*E14,1) -> 12 | G14: 1.3 | H14: =FLOOR(D14*G14,1) -> 22 | I14: 20/24/28/32 | J14: =CEILING(J$3/$D14,1) -> 9 | K14: =CEILING(K$3/$D14,1) -> 11 | L14: =CEILING(L$3/$D14,1) -> 12 | M14: =CEILING(M$3/$D14,1) -> 14 | N14: 630 | O14: =(J14-1)*(60/$N14) -> 0.76190476 | P14: =(K14-1)*(60/$N14) -> 0.95238095 | Q14: =(L14-1)*(60/$N14) -> 1.047619 | R14: =(M14-1)*(60/$N14) -> 1.2380952 | S14: =TRUNC($D14*($N14/60)) -> 178
C15: 无涡轮 | D15: 17 | E15: 0.75 | F15: =FLOOR(D15*E15,1) -> 12 | G15: 1.3 | H15: =FLOOR(D15*G15,1) -> 22 | J15: =CEILING(J$3/$D15,1) -> 9 | K15: =CEILING(K$3/$D15,1) -> 11 | L15: =CEILING(L$3/$D15,1) -> 12 | M15: =CEILING(M$3/$D15,1) -> 14 | N15: 560 | O15: =(J15-1)*(60/$N15) -> 0.85714286 | P15: =(K15-1)*(60/$N15) -> 1.0714286 | Q15: =(L15-1)*(60/$N15) -> 1.1785714 | R15: =(M15-1)*(60/$N15) -> 1.3928571 | S15: =TRUNC($D15*($N15/60)) -> 158
A16: 9 | B16: C.A.R冲锋枪 | D16: 14 | E16: 0.8 | F16: =FLOOR(D16*E16,1) -> 11 | G16: 1.3 | H16: =FLOOR(D16*G16,1) -> 18 | I16: 20/23/26/30 | J16: =CEILING(J$3/$D16,1) -> 11 | K16: =CEILING(K$3/$D16,1) -> 13 | L16: =CEILING(L$3/$D16,1) -> 15 | M16: =CEILING(M$3/$D16,1) -> 17 | N16: 930 | O16: =(J16-1)*(60/$N16) -> 0.64516129 | P16: =(K16-1)*(60/$N16) -> 0.77419355 | Q16: =(L16-1)*(60/$N16) -> 0.90322581 | R16: =(M16-1)*(60/$N16) -> 1.0322581 | S16: =TRUNC($D16*($N16/60)) -> 217
A17: 10 | B17: 转换者冲锋枪 | C17: 普通 | D17: 18 | E17: 0.8 | F17: =FLOOR(D17*E17,1) -> 14 | G17: 1.25 | H17: =FLOOR(D17*G17,1) -> 22 | I17: 18/20/22/26 | J17: =CEILING(J$3/$D17,1) -> 9 | K17: =CEILING(K$3/$D17,1) -> 10 | L17: =CEILING(L$3/$D17,1) -> 12 | M17: =CEILING(M$3/$D17,1) -> 13 | N17: 600 | O17: =(J17-1)*(60/$N17) -> 0.8 | P17: =(K17-1)*(60/$N17) -> 0.9 | Q17: =(L17-1)*(60/$N17) -> 1.1 | R17: =(M17-1)*(60/$N17) -> 1.2 | S17: =TRUNC($D17*($N17/60)) -> 180
C18: 双发 | D18: =14*2 -> 28 | E18: 0.8 | F18: =FLOOR(D18*E18,1) -> 22 | G18: 1.25 | H18: =FLOOR(D18*G18,1) -> 35 | J18: =CEILING(J$3/$D18,1) -> 6 | K18: =CEILING(K$3/$D18,1) -> 7 | L18: =CEILING(L$3/$D18,1) -> 8 | M18: =CEILING(M$3/$D18,1) -> 9 | N18: 460 | O18: =(J18-1)*(60/$N18) -> 0.65217391 | P18: =(K18-1)*(60/$N18) -> 0.7826087 | Q18: =(L18-1)*(60/$N18) -> 0.91304348 | R18: =(M18-1)*(60/$N18) -> 1.0434783 | S18: =TRUNC($D18*($N18/60)) -> 214
A19: 11 | B19: 平行步枪 | C19: 普通 | D19: 20 | E19: 0.75 | F19: =FLOOR(D19*E19,1) -> 15 | G19: 1.3 | H19: =FLOOR(D19*G19,1) -> 26 | I19: 19/23/27/29 | J19: =CEILING(J$3/$D19,1) -> 8 | K19: =CEILING(K$3/$D19,1) -> 9 | L19: =CEILING(L$3/$D19,1) -> 10 | M19: =CEILING(M$3/$D19,1) -> 12 | N19: 600 | O19: =(J19-1)*(60/$N19) -> 0.7 | P19: =(K19-1)*(60/$N19) -> 0.8 | Q19: =(L19-1)*(60/$N19) -> 0.9 | R19: =(M19-1)*(60/$N19) -> 1.1 | S19: =TRUNC($D19*($N19/60)) -> 200
C20: 彩虹子弹 | D20: 20 | E20: 0.75 | F20: =FLOOR(D20*E20,1) -> 15 | G20: 1.3 | H20: =FLOOR(D20*G20,1) -> 26 | I20: 21/25/29/31 | J20: =CEILING(J$3/$D20,1) -> 8 | K20: =CEILING(K$3/$D20,1) -> 9 | L20: =CEILING(L$3/$D20,1) -> 10 | M20: =CEILING(M$3/$D20,1) -> 12 | N20: 600 | O20: =(J20-1)*(60/$N20) -> 0.7 | P20: =(K20-1)*(60/$N20) -> 0.8 | Q20: =(L20-1)*(60/$N20) -> 0.9 | R20: =(M20-1)*(60/$N20) -> 1.1 | S20: =TRUNC($D20*($N20/60)) -> 200
A21: 12 | B21: P2020 | C21: 双持 | D21: 24 | E21: 0.9 | F21: =FLOOR(D21*E21,1) -> 21 | G21: 1.25 | H21: =FLOOR(D21*G21,1) -> 30 | I21: 18/21/24/27 | J21: =CEILING(J$3/$D21,1) -> 7 | K21: =CEILING(K$3/$D21,1) -> 8 | L21: =CEILING(L$3/$D21,1) -> 9 | M21: =CEILING(M$3/$D21,1) -> 10 | N21: 450 | O21: =(J21-1)*(60/$N21) -> 0.8 | P21: =(K21-1)*(60/$N21) -> 0.93333333 | Q21: =(L21-1)*(60/$N21) -> 1.0666667 | R21: =(M21-1)*(60/$N21) -> 1.2 | S21: =TRUNC($D21*($N21/60)) -> 180
C22: 双持-锤击点 | D22: 24 | E22: 0.9 | F22: =FLOOR(D22*E22,1) -> 21 | G22: 1.25 | H22: =FLOOR(D22*G22,1) -> 30 | J22: =CEILING(J$3/$D22,1) -> 7 | K22: =CEILING(K$3/$D22,1) -> 8 | L22: =CEILING(L$3/$D22,1) -> 9 | M22: =CEILING(M$3/$D22,1) -> 10 | N22: 450 | O22: =(J22-1)*(60/$N22) -> 0.8 | P22: =(K22-1)*(60/$N22) -> 0.93333333 | Q22: =(L22-1)*(60/$N22) -> 1.0666667 | R22: =(M22-1)*(60/$N22) -> 1.2 | S22: =TRUNC($D22*($N22/60)) -> 180
A23: 13 | B23: R-99 | D23: 12 | E23: 0.8 | F23: =FLOOR(D23*E23,1) -> 9 | G23: 1.25 | H23: =FLOOR(D23*G23,1) -> 15 | I23: 18/21/24/27 | J23: =CEILING(J$3/$D23,1) -> 13 | K23: =CEILING(K$3/$D23,1) -> 15 | L23: =CEILING(L$3/$D23,1) -> 17 | M23: =CEILING(M$3/$D23,1) -> 19 | N23: 1080 | O23: =(J23-1)*(60/$N23) -> 0.66666667 | P23: =(K23-1)*(60/$N23) -> 0.77777778 | Q23: =(L23-1)*(60/$N23) -> 0.88888889 | R23: =(M23-1)*(60/$N23) -> 1 | S23: =TRUNC($D23*($N23/60)) -> 216
A24: 14 | B24: 暴走轻机枪 | C24: 普通 | D24: 29 | E24: 0.85 | F24: =FLOOR(D24*E24,1) -> 24 | G24: 1.25 | H24: =FLOOR(D24*G24,1) -> 36 | I24: 28/32/34/40 | J24: =CEILING(J$3/$D24,1) -> 6 | K24: =CEILING(K$3/$D24,1) -> 7 | L24: =CEILING(L$3/$D24,1) -> 7 | M24: =CEILING(M$3/$D24,1) -> 8 | N24: 300 | O24: =(J24-1)*(60/$N24) -> 1 | P24: =(K24-1)*(60/$N24) -> 1.2 | Q24: =(L24-1)*(60/$N24) -> 1.2 | R24: =(M24-1)*(60/$N24) -> 1.4 | S24: =TRUNC($D24*($N24/60)) -> 145
C25: 充能 | D25: 29 | E25: 0.85 | F25: =FLOOR(D25*E25,1) -> 24 | G25: 1.25 | H25: =FLOOR(D25*G25,1) -> 36 | J25: =CEILING(J$3/$D25,1) -> 6 | K25: =CEILING(K$3/$D25,1) -> 7 | L25: =CEILING(L$3/$D25,1) -> 7 | M25: =CEILING(M$3/$D25,1) -> 8 | N25: 390 | O25: =(J25-1)*(60/$N25) -> 0.76923077 | P25: =(K25-1)*(60/$N25) -> 0.92307692 | Q25: =(L25-1)*(60/$N25) -> 0.92307692 | R25: =(M25-1)*(60/$N25) -> 1.0769231 | S25: =TRUNC($D25*($N25/60)) -> 188
A26: 15 | B26: R-301 | D26: 15 | E26: 0.75 | F26: =FLOOR(D26*E26,1) -> 11 | G26: 1.3 | H26: =FLOOR(D26*G26,1) -> 19 | I26: 21/23/28/31 | J26: =CEILING(J$3/$D26,1) -> 10 | K26: =CEILING(K$3/$D26,1) -> 12 | L26: =CEILING(L$3/$D26,1) -> 14 | M26: =CEILING(M$3/$D26,1) -> 15 | N26: 810 | O26: =(J26-1)*(60/$N26) -> 0.66666667 | P26: =(K26-1)*(60/$N26) -> 0.81481481 | Q26: =(L26-1)*(60/$N26) -> 0.96296296 | R26: =(M26-1)*(60/$N26) -> 1.037037 | S26: =TRUNC($D26*($N26/60)) -> 202
A27: 16 | B27: RE-45 | D27: 16 | E27: 0.9 | F27: =FLOOR(D27*E27,1) -> 14 | G27: 1.25 | H27: =FLOOR(D27*G27,1) -> 20 | I27: 15/18/21/24 | J27: =CEILING(J$3/$D27,1) -> 10 | K27: =CEILING(K$3/$D27,1) -> 11 | L27: =CEILING(L$3/$D27,1) -> 13 | M27: =CEILING(M$3/$D27,1) -> 15 | N27: 780 | O27: =(J27-1)*(60/$N27) -> 0.69230769 | P27: =(K27-1)*(60/$N27) -> 0.76923077 | Q27: =(L27-1)*(60/$N27) -> 0.92307692 | R27: =(M27-1)*(60/$N27) -> 1.0769231 | S27: =TRUNC($D27*($N27/60)) -> 208
A28: 17 | B28: 喷火轻机枪 | D28: 21 | E28: 0.8 | F28: =FLOOR(D28*E28,1) -> 16 | G28: 1.25 | H28: =FLOOR(D28*G28,1) -> 26 | I28: 35/40/45/50 | J28: =CEILING(J$3/$D28,1) -> 8 | K28: =CEILING(K$3/$D28,1) -> 9 | L28: =CEILING(L$3/$D28,1) -> 10 | M28: =CEILING(M$3/$D28,1) -> 11 | N28: 540 | O28: =(J28-1)*(60/$N28) -> 0.77777778 | P28: =(K28-1)*(60/$N28) -> 0.88888889 | Q28: =(L28-1)*(60/$N28) -> 1 | R28: =(M28-1)*(60/$N28) -> 1.1111111 | S28: =TRUNC($D28*($N28/60)) -> 189
A29: 18 | B29: 小帮手 | C29: 默认 | D29: 50 | E29: 0.9 | F29: =FLOOR(D29*E29,1) -> 45 | G29: 1.5 | H29: =FLOOR(D29*G29,1) -> 75 | I29: 5/6/7/8 | J29: =CEILING(J$3/$D29,1) -> 3 | K29: =CEILING(K$3/$D29,1) -> 4 | L29: =CEILING(L$3/$D29,1) -> 4 | M29: =CEILING(M$3/$D29,1) -> 5 | N29: 160 | O29: =(J29-1)*(60/$N29) -> 0.75 | P29: =(K29-1)*(60/$N29) -> 1.125 | Q29: =(L29-1)*(60/$N29) -> 1.125 | R29: =(M29-1)*(60/$N29) -> 1.5 | S29: =TRUNC($D29*($N29/60)) -> 133
C30: 彩色子弹 | D30: 50 | E30: 0.9 | F30: =FLOOR(D30*E30,1) -> 45 | G30: 1.5 | H30: =FLOOR(D30*G30,1) -> 75 | I30: 7/8/9/10 | J30: =CEILING(J$3/$D30,1) -> 3 | K30: =CEILING(K$3/$D30,1) -> 4 | L30: =CEILING(L$3/$D30,1) -> 4 | M30: =CEILING(M$3/$D30,1) -> 5 | N30: 160 | O30: =(J30-1)*(60/$N30) -> 0.75 | P30: =(K30-1)*(60/$N30) -> 1.125 | Q30: =(L30-1)*(60/$N30) -> 1.125 | R30: =(M30-1)*(60/$N30) -> 1.5 | S30: =TRUNC($D30*($N30/60)) -> 133
A31: 19 | B31: 电能冲锋枪 | C31: 默认 | D31: 16 | E31: 0.8 | F31: =FLOOR(D31*E31,1) -> 12 | G31: 1.2 | H31: =FLOOR(D31*G31,1) -> 19 | I31: 20/22//24/27 | J31: =CEILING(J$3/$D31,1) -> 10 | K31: =CEILING(K$3/$D31,1) -> 11 | L31: =CEILING(L$3/$D31,1) -> 13 | M31: =CEILING(M$3/$D31,1) -> 15 | N31: 720 | O31: =(J31-1)*(60/$N31) -> 0.75 | P31: =(K31-1)*(60/$N31) -> 0.83333333 | Q31: =(L31-1)*(60/$N31) -> 1 | R31: =(M31-1)*(60/$N31) -> 1.1666667 | S31: =TRUNC($D31*($N31/60)) -> 192
C32: 彩色子弹 | D32: 16 | E32: 0.8 | F32: =FLOOR(D32*E32,1) -> 12 | G32: 1.2 | H32: =FLOOR(D32*G32,1) -> 19 | I32: 22/24/26/29 | J32: =CEILING(J$3/$D32,1) -> 10 | K32: =CEILING(K$3/$D32,1) -> 11 | L32: =CEILING(L$3/$D32,1) -> 13 | M32: =CEILING(M$3/$D32,1) -> 15 | N32: 720 | O32: =(J32-1)*(60/$N32) -> 0.75 | P32: =(K32-1)*(60/$N32) -> 0.83333333 | Q32: =(L32-1)*(60/$N32) -> 1 | R32: =(M32-1)*(60/$N32) -> 1.1666667 | S32: =TRUNC($D32*($N32/60)) -> 192
A33: 20 | B33: 赫姆洛克 | C33: 普通 | D33: 21 | E33: 0.75 | F33: =FLOOR(D33*E33,1) -> 15 | G33: 1.4 | H33: =FLOOR(D33*G33,1) -> 29 | I33: 18/20/22/25 | J33: =CEILING(J$3/$D33,1) -> 8 | K33: =CEILING(K$3/$D33,1) -> 9 | L33: =CEILING(L$3/$D33,1) -> 10 | M33: =CEILING(M$3/$D33,1) -> 11 | N33: 462 | O33: =(J33-1)*(60/$N33) -> 0.90909091 | P33: =(K33-1)*(60/$N33) -> 1.038961 | Q33: =(L33-1)*(60/$N33) -> 1.1688312 | R33: =(M33-1)*(60/$N33) -> 1.2987013 | S33: =TRUNC($D33*($N33/60)) -> 161
A34: 21 | B34: 3030连发枪 | C34: 空投武器-普通 | D34: 71 | E34: 0.85 | F34: =FLOOR(D34*E34,1) -> 60 | G34: 1.4 | H34: =FLOOR(D34*G34,1) -> 99 | I34: 10 | J34: =CEILING(J$3/$D34,1) -> 3 | K34: =CEILING(K$3/$D34,1) -> 3 | L34: =CEILING(L$3/$D34,1) -> 3 | M34: =CEILING(M$3/$D34,1) -> 4 | N34: 105 | O34: =(J34-1)*(60/$N34) -> 1.1428571 | P34: =(K34-1)*(60/$N34) -> 1.1428571 | Q34: =(L34-1)*(60/$N34) -> 1.1428571 | R34: =(M34-1)*(60/$N34) -> 1.7142857 | S34: =TRUNC($D34*($N34/60)) -> 124
C35: 空投武器-粉碎帽 | D35: 56 | E35: 1 | F35: =FLOOR(D35*E35,1) -> 56 | G35: 1.25 | H35: =FLOOR(D35*G35,1) -> 70 | I35: 10 | J35: =CEILING(J$3/$D35,1) -> 3 | K35: =CEILING(K$3/$D35,1) -> 4 | L35: =CEILING(L$3/$D35,1) -> 4 | M35: =CEILING(M$3/$D35,1) -> 5 | N35: 140 | O35: =(J35-1)*(60/$N35) -> 0.85714286 | P35: =(K35-1)*(60/$N35) -> 1.2857143 | Q35: =(L35-1)*(60/$N35) -> 1.2857143 | R35: =(M35-1)*(60/$N35) -> 1.7142857 | S35: =TRUNC($D35*($N35/60)) -> 130
A36: 22 | B36: 波塞克 | C36: 满蓄力 | D36: 60 | E36: 0.8 | F36: =FLOOR(D36*E36,1) -> 48 | G36: 1.5 | H36: =FLOOR(D36*G36,1) -> 90 | I36: 40 | J36: =CEILING(J$3/$D36,1) -> 3 | K36: =CEILING(K$3/$D36,1) -> 3 | L36: =CEILING(L$3/$D36,1) -> 4 | M36: =CEILING(M$3/$D36,1) -> 4 | N36: 70 | O36: =(J36-1)*(60/$N36) -> 1.7142857 | P36: =(K36-1)*(60/$N36) -> 1.7142857 | Q36: =(L36-1)*(60/$N36) -> 2.5714286 | R36: =(M36-1)*(60/$N36) -> 2.5714286 | S36: =TRUNC($D36*($N36/60)) -> 70
C37: 满蓄力-爆炸充能 | D37: =50+25 -> 75 | E37: 0.8 | F37: =FLOOR(D37*E37,1) -> 60 | G37: 1.5 | H37: =FLOOR(D37*G37,1) -> 112 | I37: 40 | J37: =CEILING(J$3/$D37,1) -> 2 | K37: =CEILING(K$3/$D37,1) -> 3 | L37: =CEILING(L$3/$D37,1) -> 3 | M37: =CEILING(M$3/$D37,1) -> 3 | N37: 70 | O37: =(J37-1)*(60/$N37) -> 0.85714286 | P37: =(K37-1)*(60/$N37) -> 1.7142857 | Q37: =(L37-1)*(60/$N37) -> 1.7142857 | R37: =(M37-1)*(60/$N37) -> 1.7142857 | S37: =TRUNC($D37*($N37/60)) -> 87
A38: 23 | B38: G7侦察枪 | D38: 33 | E38: 0.75 | F38: =FLOOR(D38*E38,1) -> 24 | G38: 1.45 | H38: =FLOOR(D38*G38,1) -> 47 | I38: 10/12/14/16 | J38: =CEILING(J$3/$D38,1) -> 5 | K38: =CEILING(K$3/$D38,1) -> 6 | L38: =CEILING(L$3/$D38,1) -> 7 | M38: =CEILING(M$3/$D38,1) -> 7 | N38: 246 | O38: =(J38-1)*(60/$N38) -> 0.97560976 | P38: =(K38-1)*(60/$N38) -> 1.2195122 | Q38: =(L38-1)*(60/$N38) -> 1.4634146 | R38: =(M38-1)*(60/$N38) -> 1.4634146 | S38: =TRUNC($D38*($N38/60)) -> 135
A39: 24 | B39: 獒犬霰弹枪 | C39: 紫枪栓 | D39: 95 | E39: 1 | F39: =FLOOR(D39*E39,1) -> 95 | G39: 1 | H39: =FLOOR(D39*G39,1) -> 95 | I39: 5 | J39: =CEILING(J$3/$D39,1) -> 2 | K39: =CEILING(K$3/$D39,1) -> 2 | L39: =CEILING(L$3/$D39,1) -> 3 | M39: =CEILING(M$3/$D39,1) -> 3 | N39: 79 | O39: =(J39-1)*(60/$N39) -> 0.75949367 | P39: =(K39-1)*(60/$N39) -> 0.75949367 | Q39: =(L39-1)*(60/$N39) -> 1.5189873 | R39: =(M39-1)*(60/$N39) -> 1.5189873 | S39: =TRUNC($D39*($N39/60)) -> 125
A40: 25 | B40: 三重狙击枪 | C40: 开镜 | D40: 66 | E40: 0.9 | F40: =FLOOR(D40*E40,1) -> 59 | G40: 1.5 | H40: =FLOOR(D40*G40,1) -> 99 | I40: 6/7/8/10 | J40: =CEILING(J$3/$D40,1) -> 3 | K40: =CEILING(K$3/$D40,1) -> 3 | L40: =CEILING(L$3/$D40,1) -> 4 | M40: =CEILING(M$3/$D40,1) -> 4 | N40: 77 | O40: =(J40-1)*(60/$N40) -> 1.5584416 | P40: =(K40-1)*(60/$N40) -> 1.5584416 | Q40: =(L40-1)*(60/$N40) -> 2.3376623 | R40: =(M40-1)*(60/$N40) -> 2.3376623 | S40: =TRUNC($D40*($N40/60)) -> 84
...

Sheet 赛季调整
A1: 赛季 | B1: 武器列表 | D1: 单发伤害 | I1: 弹匣容量 | J1: 击杀需要的子弹数量 | N1: RPM | O1: TTK（全打胸，单位秒） | S1: DFS 第一秒内伤害 （全打胸） | T1: 备注
D2: 胸部 | E2: 腿部 | G2: 头部 | J2: 白甲 （150） | K2: 蓝甲 （175） | L2: 紫甲 （200） | M2: 红甲 （225） | O2: 白甲 （150） | P2: 蓝甲 （175） | Q2: 紫甲 （200） | R2: 红甲 （225）
E3: 伤害倍率 | F3: 具体数值 | G3: 伤害倍率 | H3: 具体数值 | J3: 150 | K3: 175 | L3: 200 | M3: 225 | O3: 150 | P3: 175 | Q3: 200 | R3: 225
A4: 29 | B4: 转换者冲锋枪 | C4: 普通 | D4: 19 | E4: 0.8 | F4: =FLOOR(D4*E4,1) -> 15 | G4: 1.25 | H4: =FLOOR(D4*G4,1) -> 23 | I4: 20/24/26/30 | J4: =CEILING(J$3/$D4,1) -> 8 | K4: =CEILING(K$3/$D4,1) -> 10 | L4: =CEILING(L$3/$D4,1) -> 11 | M4: =CEILING(M$3/$D4,1) -> 12 | N4: 600 | O4: =(J4-1)*(60/$N4) -> 0.7 | P4: =(K4-1)*(60/$N4) -> 0.9 | Q4: =(L4-1)*(60/$N4) -> 1 | R4: =(M4-1)*(60/$N4) -> 1.1 | S4: =TRUNC($D4*($N4/60)) -> 190 | T4: 削弱了1点伤害
C5: 双发 | D5: =15*2 -> 30 | E5: 0.8 | F5: =FLOOR(D5*E5,1) -> 24 | G5: 1.25 | H5: =FLOOR(D5*G5,1) -> 37 | J5: =CEILING(J$3/$D5,1) -> 5 | K5: =CEILING(K$3/$D5,1) -> 6 | L5: =CEILING(L$3/$D5,1) -> 7 | M5: =CEILING(M$3/$D5,1) -> 8 | N5: 460 | O5: =(J5-1)*(60/$N5) -> 0.52173913 | P5: =(K5-1)*(60/$N5) -> 0.65217391 | Q5: =(L5-1)*(60/$N5) -> 0.7826087 | R5: =(M5-1)*(60/$N5) -> 0.91304348 | S5: =TRUNC($D5*($N5/60)) -> 230
A6: 30 | B6: 转换者冲锋枪 | C6: 普通 | D6: 18 | E6: 0.8 | F6: =FLOOR(D6*E6,1) -> 14 | G6: 1.25 | H6: =FLOOR(D6*G6,1) -> 22 | I6: 18/20/22/26 | J6: =CEILING(J$3/$D6,1) -> 9 | K6: =CEILING(K$3/$D6,1) -> 10 | L6: =CEILING(L$3/$D6,1) -> 12 | M6: =CEILING(M$3/$D6,1) -> 13 | N6: 600 | O6: =(J6-1)*(60/$N6) -> 0.8 | P6: =(K6-1)*(60/$N6) -> 0.9 | Q6: =(L6-1)*(60/$N6) -> 1.1 | R6: =(M6-1)*(60/$N6) -> 1.2 | S6: =TRUNC($D6*($N6/60)) -> 180
C7: 双发 | D7: =14*2 -> 28 | E7: 0.8 | F7: =FLOOR(D7*E7,1) -> 22 | G7: 1.25 | H7: =FLOOR(D7*G7,1) -> 35 | J7: =CEILING(J$3/$D7,1) -> 6 | K7: =CEILING(K$3/$D7,1) -> 7 | L7: =CEILING(L$3/$D7,1) -> 8 | M7: =CEILING(M$3/$D7,1) -> 9 | N7: 460 | O7: =(J7-1)*(60/$N7) -> 0.65217391 | P7: =(K7-1)*(60/$N7) -> 0.7826087 | Q7: =(L7-1)*(60/$N7) -> 0.91304348 | R7: =(M7-1)*(60/$N7) -> 1.0434783 | S7: =TRUNC($D7*($N7/60)) -> 214
A8: 29 | B8: R-99 | D8: 13 | E8: 0.8 | F8: =FLOOR(D8*E8,1) -> 10 | G8: 1.25 | H8: =FLOOR(D8*G8,1) -> 16 | I8: 18/21/24/27 | J8: =CEILING(J$3/$D8,1) -> 12 | K8: =CEILING(K$3/$D8,1) -> 14 | L8: =CEILING(L$3/$D8,1) -> 16 | M8: =CEILING(M$3/$D8,1) -> 18 | N8: 1080 | O8: =(J8-1)*(60/$N8) -> 0.61111111 | P8: =(K8-1)*(60/$N8) -> 0.72222222 | Q8: =(L8-1)*(60/$N8) -> 0.83333333 | R8: =(M8-1)*(60/$N8) -> 0.94444444 | S8: =TRUNC($D8*($N8/60)) -> 234 | T8: 削弱了1点伤害
A9: 30 | B9: R-99 | D9: 12 | E9: 0.8 | F9: =FLOOR(D9*E9,1) -> 9 | G9: 1.25 | H9: =FLOOR(D9*G9,1) -> 15 | I9: 18/21/24/27 | J9: =CEILING(J$3/$D9,1) -> 13 | K9: =CEILING(K$3/$D9,1) -> 15 | L9: =CEILING(L$3/$D9,1) -> 17 | M9: =CEILING(M$3/$D9,1) -> 19 | N9: 1080 | O9: =(J9-1)*(60/$N9) -> 0.66666667 | P9: =(K9-1)*(60/$N9) -> 0.77777778 | Q9: =(L9-1)*(60/$N9) -> 0.88888889 | R9: =(M9-1)*(60/$N9) -> 1 | S9: =TRUNC($D9*($N9/60)) -> 216
A10: 29 | B10: RE-45 | D10: 17 | E10: 0.9 | F10: =FLOOR(D10*E10,1) -> 15 | G10: 1.25 | H10: =FLOOR(D10*G10,1) -> 21 | I10: 15/18/21/24 | J10: =CEILING(J$3/$D10,1) -> 9 | K10: =CEILING(K$3/$D10,1) -> 11 | L10: =CEILING(L$3/$D10,1) -> 12 | M10: =CEILING(M$3/$D10,1) -> 14 | N10: 780 | O10: =(J10-1)*(60/$N10) -> 0.61538462 | P10: =(K10-1)*(60/$N10) -> 0.76923077 | Q10: =(L10-1)*(60/$N10) -> 0.84615385 | R10: =(M10-1)*(60/$N10) -> 1 | S10: =TRUNC($D10*($N10/60)) -> 221 | T10: 削弱了1点伤害
A11: 30 | B11: RE-45 | D11: 16 | E11: 0.9 | F11: =FLOOR(D11*E11,1) -> 14 | G11: 1.25 | H11: =FLOOR(D11*G11,1) -> 20 | I11: 15/18/21/24 | J11: =CEILING(J$3/$D11,1) -> 10 | K11: =CEILING(K$3/$D11,1) -> 11 | L11: =CEILING(L$3/$D11,1) -> 13 | M11: =CEILING(M$3/$D11,1) -> 15 | N11: 780 | O11: =(J11-1)*(60/$N11) -> 0.69230769 | P11: =(K11-1)*(60/$N11) -> 0.76923077 | Q11: =(L11-1)*(60/$N11) -> 0.92307692 | R11: =(M11-1)*(60/$N11) -> 1.0769231 | S11: =TRUNC($D11*($N11/60)) -> 208
A12: 29 | B12: 赫姆洛克 | C12: 普通 | D12: 22 | E12: 0.75 | F12: =FLOOR(D12*E12,1) -> 16 | G12: 1.4 | H12: =FLOOR(D12*G12,1) -> 30 | I12: 18/20/22/25 | J12: =CEILING(J$3/$D12,1) -> 7 | K12: =CEILING(K$3/$D12,1) -> 8 | L12: =CEILING(L$3/$D12,1) -> 10 | M12: =CEILING(M$3/$D12,1) -> 11 | N12: 462 | O12: =(J12-1)*(60/$N12) -> 0.77922078 | P12: =(K12-1)*(60/$N12) -> 0.90909091 | Q12: =(L12-1)*(60/$N12) -> 1.1688312 | R12: =(M12-1)*(60/$N12) -> 1.2987013 | S12: =TRUNC($D12*($N12/60)) -> 169 | T12: 削弱了1点伤害
A13: 30 | B13: 赫姆洛克 | C13: 普通 | D13: 21 | E13: 0.75 | F13: =FLOOR(D13*E13,1) -> 15 | G13: 1.4 | H13: =FLOOR(D13*G13,1) -> 29 | I13: 18/20/22/25 | J13: =CEILING(J$3/$D13,1) -> 8 | K13: =CEILING(K$3/$D13,1) -> 9 | L13: =CEILING(L$3/$D13,1) -> 10 | M13: =CEILING(M$3/$D13,1) -> 11 | N13: 462 | O13: =(J13-1)*(60/$N13) -> 0.90909091 | P13: =(K13-1)*(60/$N13) -> 1.038961 | Q13: =(L13-1)*(60/$N13) -> 1.1688312 | R13: =(M13-1)*(60/$N13) -> 1.2987013 | S13: =TRUNC($D13*($N13/60)) -> 161
A14: 29 | B14: 3030连发枪 | C14: 空投武器-普通 | D14: 60 | E14: 0.85 | F14: =FLOOR(D14*E14,1) -> 51 | G14: 1.4 | H14: =FLOOR(D14*G14,1) -> 84 | I14: 10 | J14: =CEILING(J$3/$D14,1) -> 3 | K14: =CEILING(K$3/$D14,1) -> 3 | L14: =CEILING(L$3/$D14,1) -> 4 | M14: =CEILING(M$3/$D14,1) -> 4 | N14: 105 | O14: =(J14-1)*(60/$N14) -> 1.1428571 | P14: =(K14-1)*(60/$N14) -> 1.1428571 | Q14: =(L14-1)*(60/$N14) -> 1.7142857 | R14: =(M14-1)*(60/$N14) -> 1.7142857 | S14: =TRUNC($D14*($N14/60)) -> 105 | T14: 加强了11点伤害
C15: 空投武器-粉碎帽 | D15: 56 | E15: 1 | F15: =FLOOR(D15*E15,1) -> 56 | G15: 1.25 | H15: =FLOOR(D15*G15,1) -> 70 | I15: 10 | J15: =CEILING(J$3/$D15,1) -> 3 | K15: =CEILING(K$3/$D15,1) -> 4 | L15: =CEILING(L$3/$D15,1) -> 4 | M15: =CEILING(M$3/$D15,1) -> 5 | N15: 140 | O15: =(J15-1)*(60/$N15) -> 0.85714286 | P15: =(K15-1)*(60/$N15) -> 1.2857143 | Q15: =(L15-1)*(60/$N15) -> 1.2857143 | R15: =(M15-1)*(60/$N15) -> 1.7142857 | S15: =TRUNC($D15*($N15/60)) -> 130
A16: 30 | B16: 3030连发枪 | C16: 空投武器-普通 | D16: 71 | E16: 0.85 | F16: =FLOOR(D16*E16,1) -> 60 | G16: 1.4 | H16: =FLOOR(D16*G16,1) -> 99 | I16: 10 | J16: =CEILING(J$3/$D16,1) -> 3 | K16: =CEILING(K$3/$D16,1) -> 3 | L16: =CEILING(L$3/$D16,1) -> 3 | M16: =CEILING(M$3/$D16,1) -> 4 | N16: 105 | O16: =(J16-1)*(60/$N16) -> 1.1428571 | P16: =(K16-1)*(60/$N16) -> 1.1428571 | Q16: =(L16-1)*(60/$N16) -> 1.1428571 | R16: =(M16-1)*(60/$N16) -> 1.7142857 | S16: =TRUNC($D16*($N16/60)) -> 124
C17: 空投武器-粉碎帽 | D17: 56 | E17: 1 | F17: =FLOOR(D17*E17,1) -> 56 | G17: 1.25 | H17: =FLOOR(D17*G17,1) -> 70 | I17: 10 | J17: =CEILING(J$3/$D17,1) -> 3 | K17: =CEILING(K$3/$D17,1) -> 4 | L17: =CEILING(L$3/$D17,1) -> 4 | M17: =CEILING(M$3/$D17,1) -> 5 | N17: 140 | O17: =(J17-1)*(60/$N17) -> 0.85714286 | P17: =(K17-1)*(60/$N17) -> 1.2857143 | Q17: =(L17-1)*(60/$N17) -> 1.2857143 | R17: =(M17-1)*(60/$N17) -> 1.7142857 | S17: =TRUNC($D17*($N17/60)) -> 130
A18: 29 | B18: G7侦察枪 | C18: 空投武器 | D18: 37 | E18: 0.75 | F18: =FLOOR(D18*E18,1) -> 27 | G18: 1.45 | H18: =FLOOR(D18*G18,1) -> 53 | I18: 18 | J18: =CEILING(J$3/$D18,1) -> 5 | K18: =CEILING(K$3/$D18,1) -> 5 | L18: =CEILING(L$3/$D18,1) -> 6 | M18: =CEILING(M$3/$D18,1) -> 7 | N18: 246 | O18: =(J18-1)*(60/$N18) -> 0.97560976 | P18: =(K18-1)*(60/$N18) -> 0.97560976 | Q18: =(L18-1)*(60/$N18) -> 1.2195122 | R18: =(M18-1)*(60/$N18) -> 1.4634146 | S18: =TRUNC($D18*($N18/60)) -> 151 | T18: 出空投，削弱了4点伤害
A19: 30 | B19: G7侦察枪 | D19: 33 | E19: 0.75 | F19: =FLOOR(D19*E19,1) -> 24 | G19: 1.45 | H19: =FLOOR(D19*G19,1) -> 47 | I19: 10/12/14/16 | J19: =CEILING(J$3/$D19,1) -> 5 | K19: =CEILING(K$3/$D19,1) -> 6 | L19: =CEILING(L$3/$D19,1) -> 7 | M19: =CEILING(M$3/$D19,1) -> 7 | N19: 246 | O19: =(J19-1)*(60/$N19) -> 0.97560976 | P19: =(K19-1)*(60/$N19) -> 1.2195122 | Q19: =(L19-1)*(60/$N19) -> 1.4634146 | R19: =(M19-1)*(60/$N19) -> 1.4634146 | S19: =TRUNC($D19*($N19/60)) -> 135

Sheet 容错计算
A1: 序号 | B1: 武器名称 | D1: 单发伤害 （胸部） | E1: 最大弹容量 | F1: 击杀紫甲 需要的子弹数 | G1: 子弹容错数 | H1: 紫甲秒杀 容错率 | I1: RPM | J1: TTM （弹匣打空时间） 单位：秒 | K1: TTK （击杀紫甲） 单位：秒 | L1: 允许空枪的时间 单位：秒 | M1: 备注
A4: 1 | B4: 塞拉轻机枪 | D4: =ttk_dfs!D4 -> 14 | E4: 173 | F4: =ttk_dfs!L4 -> 15 | G4: =FLOOR((D4*E4-200)/D4,1) -> 158 | H4: =G4/E4 -> 0.9132948 | I4: 1200 | J4: =(E4-1)*(60/I4) -> 8.6 | K4: =ttk_dfs!Q4 -> 0.7 | L4: =J4-K4 -> 7.9
A5: 2 | B5: 专注轻机枪 | C5: 有涡轮 | D5: =ttk_dfs!D5 -> 16 | E5: 48 | F5: =ttk_dfs!L5 -> 13 | G5: =FLOOR((D5*E5-200)/D5,1) -> 35 | H5: =G5/E5 -> 0.72916667 | I5: 900 | J5: =(E5-1)*(60/I5) -> 3.1333333 | K5: =ttk_dfs!Q5 -> 0.8 | L5: =J5-K5 -> 2.3333333
C6: 无涡轮 | D6: =ttk_dfs!D6 -> 16 | E6: 48 | F6: =ttk_dfs!L6 -> 13 | G6: =FLOOR((D6*E6-200)/D6,1) -> 35 | H6: =G6/E6 -> 0.72916667 | I6: 300 | J6: =(E6-1)*(60/I6) -> 9.4 | K6: =ttk_dfs!Q6 -> 2.4 | L6: =J6-K6 -> 7
A7: 3 | B7: L-star | C7: 空投武器 | D7: =ttk_dfs!D7 -> 22 | E7: 28 | F7: =ttk_dfs!L7 -> 10 | G7: =FLOOR((D7*E7-200)/D7,1) -> 18 | H7: =G7/E7 -> 0.64285714 | I7: 600 | J7: =(E7-1)*(60/I7) -> 2.7 | K7: =ttk_dfs!Q7 -> 0.9 | L7: =J7-K7 -> 1.8
A8: 4 | B8: 猎兽冲锋枪 | C8: 全自动 | D8: =ttk_dfs!D8 -> 17 | E8: 35 | F8: =ttk_dfs!L8 -> 12 | G8: =FLOOR((D8*E8-200)/D8,1) -> 23 | H8: =G8/E8 -> 0.65714286 | I8: 800 | J8: =(E8-1)*(60/I8) -> 2.55 | K8: =ttk_dfs!Q8 -> 0.825 | L8: =J8-K8 -> 1.725
C9: 五连发 | D9: =ttk_dfs!D9 -> 16 | E9: 35 | F9: =ttk_dfs!L9 -> 13 | G9: =FLOOR((D9*E9-200)/D9,1) -> 22 | H9: =G9/E9 -> 0.62857143 | I9: 820 | J9: =(E9-1)*(60/I9) -> 2.4878049 | K9: =ttk_dfs!Q9 -> 0.87804878 | L9: =J9-K9 -> 1.6097561
A10: 5 | B10: 哈沃克 | D10: =ttk_dfs!D10 -> 20 | E10: 29 | F10: =ttk_dfs!L10 -> 10 | G10: =FLOOR((D10*E10-200)/D10,1) -> 19 | H10: =G10/E10 -> 0.65517241 | I10: 672 | J10: =(E10-1)*(60/I10) -> 2.5 | K10: =ttk_dfs!Q10 -> 0.80357143 | L10: =J10-K10 -> 1.6964286
A11: 6 | B11: Eva-8 | C11: 紫枪栓 | D11: =ttk_dfs!D11 -> 56 | E11: 8 | F11: =ttk_dfs!L11 -> 4 | G11: =FLOOR((D11*E11-200)/D11,1) -> 4 | H11: =G11/E11 -> 0.5 | I11: 200 | J11: =(E11-1)*(60/I11) -> 2.1 | K11: =ttk_dfs!Q11 -> 0.9 | L11: =J11-K11 -> 1.2
C12: 紫枪栓+双发扳机 | D12: =ttk_dfs!D12 -> 102 | E12: 8 | F12: =ttk_dfs!L12 -> 2 | G12: =FLOOR((D12*E12-200)/D12,1) -> 6 | H12: =G12/E12 -> 0.75 | I12: 43 | J12: =(E12-1)*(60/I12) -> 9.7674419 | K12: =ttk_dfs!Q12 -> 1.3953488 | L12: =J12-K12 -> 8.372093
A13: 7 | B13: 莫桑比克 | C13: 双持-紫枪栓 | D13: =ttk_dfs!D13 -> 51 | E13: 10 | F13: =ttk_dfs!L13 -> 4 | G13: =FLOOR((D13*E13-200)/D13,1) -> 6 | H13: =G13/E13 -> 0.6 | I13: 210 | J13: =(E13-1)*(60/I13) -> 2.5714286 | K13: =ttk_dfs!Q13 -> 0.85714286 | L13: =J13-K13 -> 1.7142857
A14: 8 | B14: 复仇女神 | C14: 涡轮 | D14: =ttk_dfs!D14 -> 17 | E14: 32 | F14: =ttk_dfs!L14 -> 12 | G14: =FLOOR((D14*E14-200)/D14,1) -> 20 | H14: =G14/E14 -> 0.625 | I14: 630 | J14: =(E14-1)*(60/I14) -> 2.952381 | K14: =ttk_dfs!Q14 -> 1.047619 | L14: =J14-K14 -> 1.9047619
C15: 无涡轮 | D15: =ttk_dfs!D15 -> 17 | E15: 32 | F15: =ttk_dfs!L15 -> 12 | G15: =FLOOR((D15*E15-200)/D15,1) -> 20 | H15: =G15/E15 -> 0.625 | I15: 560 | J15: =(E15-1)*(60/I15) -> 3.3214286 | K15: =ttk_dfs!Q15 -> 1.1785714 | L15: =J15-K15 -> 2.1428571
A16: 9 | B16: C.A.R冲锋枪 | D16: =ttk_dfs!D16 -> 14 | E16: 30 | F16: =ttk_dfs!L16 -> 15 | G16: =FLOOR((D16*E16-200)/D16,1) -> 15 | H16: =G16/E16 -> 0.5 | I16: 930 | J16: =(E16-1)*(60/I16) -> 1.8709677 | K16: =ttk_dfs!Q16 -> 0.90322581 | L16: =J16-K16 -> 0.96774194
A17: 10 | B17: 转换者冲锋枪 | C17: 普通 | D17: =ttk_dfs!D17 -> 18 | E17: 26 | F17: =ttk_dfs!L17 -> 12 | G17: =FLOOR((D17*E17-200)/D17,1) -> 14 | H17: =G17/E17 -> 0.53846154 | I17: 600 | J17: =(E17-1)*(60/I17) -> 2.5 | K17: =ttk_dfs!Q17 -> 1.1 | L17: =J17-K17 -> 1.4
C18: 双发 | D18: =ttk_dfs!D18 -> 28 | E18: 26 | F18: =ttk_dfs!L18*2 -> 16 | G18: =FLOOR((D18*E18-200)/D18,1) -> 18 | H18: =G18/E18 -> 0.69230769 | I18: 460 | J18: =(E18-1)*(60/I18) -> 3.2608696 | K18: =ttk_dfs!Q18 -> 0.91304348 | L18: =J18-K18 -> 2.3478261
A19: 11 | B19: 平行步枪 | C19: 普通 | D19: =ttk_dfs!D19 -> 20 | E19: 29 | F19: =ttk_dfs!L19 -> 10 | G19: =FLOOR((D19*E19-200)/D19,1) -> 19 | H19: =G19/E19 -> 0.65517241 | I19: 600 | J19: =(E19-1)*(60/I19) -> 2.8 | K19: =ttk_dfs!Q19 -> 0.9 | L19: =J19-K19 -> 1.9
C20: 彩虹子弹 | D20: =ttk_dfs!D20 -> 20 | E20: 31 | F20: =ttk_dfs!L20 -> 10 | G20: =FLOOR((D20*E20-200)/D20,1) -> 21 | H20: =G20/E20 -> 0.67741935 | I20: 600 | J20: =(E20-1)*(60/I20) -> 3 | K20: =ttk_dfs!Q20 -> 0.9 | L20: =J20-K20 -> 2.1
A21: 12 | B21: P2020 | C21: 双持 | D21: =ttk_dfs!D21 -> 24 | E21: 27 | F21: =ttk_dfs!L21 -> 9 | G21: =FLOOR((D21*E21-200)/D21,1) -> 18 | H21: =G21/E21 -> 0.66666667 | I21: 450 | J21: =(E21-1)*(60/I21) -> 3.4666667 | K21: =ttk_dfs!Q21 -> 1.0666667 | L21: =J21-K21 -> 2.4
C22: 双持-锤击点 | D22: =ttk_dfs!D22 -> 24 | E22: 27 | F22: =ttk_dfs!L22 -> 9 | G22: =FLOOR((D22*E22-200)/D22,1) -> 18 | H22: =G22/E22 -> 0.66666667 | I22: 450 | J22: =(E22-1)*(60/I22) -> 3.4666667 | K22: =ttk_dfs!Q22 -> 1.0666667 | L22: =J22-K22 -> 2.4
A23: 13 | B23: R-99 | D23: =ttk_dfs!D23 -> 12 | E23: 27 | F23: =ttk_dfs!L23 -> 17 | G23: =FLOOR((D23*E23-200)/D23,1) -> 10 | H23: =G23/E23 -> 0.37037037 | I23: 1080 | J23: =(E23-1)*(60/I23) -> 1.4444444 | K23: =ttk_dfs!Q23 -> 0.88888889 | L23: =J23-K23 -> 0.55555556
A24: 14 | B24: 暴走轻机枪 | C24: 普通 | D24: =ttk_dfs!D24 -> 29 | E24: 40 | F24: =ttk_dfs!L24 -> 7 | G24: =FLOOR((D24*E24-200)/D24,1) -> 33 | H24: =G24/E24 -> 0.825 | I24: 300 | J24: =(E24-1)*(60/I24) -> 7.8 | K24: =ttk_dfs!Q24 -> 1.2 | L24: =J24-K24 -> 6.6
C25: 充能 | D25: =ttk_dfs!D25 -> 29 | E25: 40 | F25: =ttk_dfs!L25 -> 7 | G25: =FLOOR((D25*E25-200)/D25,1) -> 33 | H25: =G25/E25 -> 0.825 | I25: 390 | J25: =(E25-1)*(60/I25) -> 6 | K25: =ttk_dfs!Q25 -> 0.92307692 | L25: =J25-K25 -> 5.0769231
A26: 15 | B26: R-301 | D26: =ttk_dfs!D26 -> 15 | E26: 31 | F26: =ttk_dfs!L26 -> 14 | G26: =FLOOR((D26*E26-200)/D26,1) -> 17 | H26: =G26/E26 -> 0.5483871 | I26: 810 | J26: =(E26-1)*(60/I26) -> 2.2222222 | K26: =ttk_dfs!Q26 -> 0.96296296 | L26: =J26-K26 -> 1.2592593
A27: 16 | B27: RE-45 | D27: =ttk_dfs!D27 -> 16 | E27: 24 | F27: =ttk_dfs!L27 -> 13 | G27: =FLOOR((D27*E27-200)/D27,1) -> 11 | H27: =G27/E27 -> 0.45833333 | I27: 780 | J27: =(E27-1)*(60/I27) -> 1.7692308 | K27: =ttk_dfs!Q27 -> 0.92307692 | L27: =J27-K27 -> 0.84615385
A28: 17 | B28: 喷火轻机枪 | D28: =ttk_dfs!D28 -> 21 | E28: 50 | F28: =ttk_dfs!L28 -> 10 | G28: =FLOOR((D28*E28-200)/D28,1) -> 40 | H28: =G28/E28 -> 0.8 | I28: 540 | J28: =(E28-1)*(60/I28) -> 5.4444444 | K28: =ttk_dfs!Q28 -> 1 | L28: =J28-K28 -> 4.4444444
A29: 18 | B29: 小帮手 | C29: 默认 | D29: =ttk_dfs!D29 -> 50 | E29: 8 | F29: =ttk_dfs!L29 -> 4 | G29: =FLOOR((D29*E29-200)/D29,1) -> 4 | H29: =G29/E29 -> 0.5 | I29: 160 | J29: =(E29-1)*(60/I29) -> 2.625 | K29: =ttk_dfs!Q29 -> 1.125 | L29: =J29-K29 -> 1.5
C30: 彩色子弹 | D30: =ttk_dfs!D30 -> 50 | E30: 10 | F30: =ttk_dfs!L30 -> 4 | G30: =FLOOR((D30*E30-200)/D30,1) -> 6 | H30: =G30/E30 -> 0.6 | I30: 160 | J30: =(E30-1)*(60/I30) -> 3.375 | K30: =ttk_dfs!Q30 -> 1.125 | L30: =J30-K30 -> 2.25
A31: 19 | B31: 电能冲锋枪 | C31: 默认 | D31: =ttk_dfs!D31 -> 16 | E31: 27 | F31: =ttk_dfs!L31 -> 13 | G31: =FLOOR((D31*E31-200)/D31,1) -> 14 | H31: =G31/E31 -> 0.51851852 | I31: 720 | J31: =(E31-1)*(60/I31) -> 2.1666667 | K31: =ttk_dfs!Q31 -> 1 | L31: =J31-K31 -> 1.1666667
C32: 彩色子弹 | D32: =ttk_dfs!D32 -> 16 | E32: 29 | F32: =ttk_dfs!L32 -> 13 | G32: =FLOOR((D32*E32-200)/D32,1) -> 16 | H32: =G32/E32 -> 0.55172414 | I32: 720 | J32: =(E32-1)*(60/I32) -> 2.3333333 | K32: =ttk_dfs!Q32 -> 1 | L32: =J32-K32 -> 1.3333333
A33: 20 | B33: 赫姆洛克 | C33: 普通 | D33: =ttk_dfs!D33 -> 21 | E33: 25 | F33: =ttk_dfs!L33 -> 10 | G33: =FLOOR((D33*E33-200)/D33,1) -> 15 | H33: =G33/E33 -> 0.6 | I33: 462 | J33: =(E33-1)*(60/I33) -> 3.1168831 | K33: =ttk_dfs!Q33 -> 1.1688312 | L33: =J33-K33 -> 1.9480519
A34: 21 | B34: 3030连发枪 | C34: 空投武器-普通 | D34: =ttk_dfs!D34 -> 71 | E34: 10 | F34: =ttk_dfs!L34 -> 3 | G34: =FLOOR((D34*E34-200)/D34,1) -> 7 | H34: =G34/E34 -> 0.7 | I34: 105 | J34: =(E34-1)*(60/I34) -> 5.1428571 | K34: =ttk_dfs!Q34 -> 1.1428571 | L34: =J34-K34 -> 4
C35: 空投武器-粉碎帽 | D35: =ttk_dfs!D35 -> 56 | E35: 10 | F35: =ttk_dfs!L35 -> 4 | G35: =FLOOR((D35*E35-200)/D35,1) -> 6 | H35: =G35/E35 -> 0.6 | I35: 140 | J35: =(E35-1)*(60/I35) -> 3.8571429 | K35: =ttk_dfs!Q35 -> 1.2857143 | L35: =J35-K35 -> 2.5714286
A36: 22 | B36: 波塞克 | C36: 满蓄力 | D36: =ttk_dfs!D36 -> 60 | E36: 40 | F36: =ttk_dfs!L36 -> 4 | G36: =FLOOR((D36*E36-200)/D36,1) -> 36 | H36: =G36/E36 -> 0.9 | I36: 70 | J36: =(E36-1)*(60/I36) -> 33.428571 | K36: =ttk_dfs!Q36 -> 2.5714286 | L36: =J36-K36 -> 30.857143 | M36: 波塞克是复合弓，只能把子弹全部打空
C37: 满蓄力-爆炸充能 | D37: =ttk_dfs!D37 -> 75 | E37: 40 | F37: =ttk_dfs!L37 -> 3 | G37: =FLOOR((D37*E37-200)/D37,1) -> 37 | H37: =G37/E37 -> 0.925 | I37: 70 | J37: =(E37-1)*(60/I37) -> 33.428571 | K37: =ttk_dfs!Q37 -> 1.7142857 | L37: =J37-K37 -> 31.714286
A38: 23 | B38: G7侦察枪 | D38: =ttk_dfs!D38 -> 33 | E38: 16 | F38: =ttk_dfs!L38 -> 7 | G38: =FLOOR((D38*E38-200)/D38,1) -> 9 | H38: =G38/E38 -> 0.5625 | I38: 246 | J38: =(E38-1)*(60/I38) -> 3.6585366 | K38: =ttk_dfs!Q38 -> 1.4634146 | L38: =J38-K38 -> 2.195122
A39: 24 | B39: 獒犬霰弹枪 | C39: 紫枪栓 | D39: =ttk_dfs!D39 -> 95 | E39: 5 | F39: =ttk_dfs!L39 -> 3 | G39: =FLOOR((D39*E39-200)/D39,1) -> 2 | H39: =G39/E39 -> 0.4 | I39: 79 | J39: =(E39-1)*(60/I39) -> 3.0379747 | K39: =ttk_dfs!Q39 -> 1.5189873 | L39: =J39-K39 -> 1.5189873
A40: 25 | B40: 三重狙击枪 | C40: 开镜 | D40: =ttk_dfs!D40 -> 66 | E40: 10 | F40: =ttk_dfs!L40 -> 4 | G40: =FLOOR((D40*E40-200)/D40,1) -> 6 | H40: =G40/E40 -> 0.6 | I40: 77 | J40: =(E40-1)*(60/I40) -> 7.012987 | K40: =ttk_dfs!Q40 -> 2.3376623 | L40: =J40-K40 -> 4.6753247
C41: 腰射 | D41: =ttk_dfs!D41 -> 66 | E41: 10 | F41: =ttk_dfs!L41 -> 4 | G41: =FLOOR((D41*E41-200)/D41,1) -> 6 | H41: =G41/E41 -> 0.6 | I41: 107 | J41: =(E41-1)*(60/I41) -> 5.046729 | K41: =ttk_dfs!Q41 -> 1.682243 | L41: =J41-K41 -> 3.364486
A42: 26 | B42: 充能步枪 | C42: 普通 | D42: =ttk_dfs!D42 -> 75 | E42: 9 | F42: =ttk_dfs!L42 -> 3 | G42: =FLOOR((D42*E42-200)/D42,1) -> 6 | H42: =G42/E42 -> 0.66666667 | I42: 41 | J42: =(E42-1)*(60/I42) -> 11.707317 | K42: =ttk_dfs!Q42 -> 2.9268293 | L42: =J42-K42 -> 8.7804878
...
