Workbook

Sheet 卡牌总表
A1: 序号 | B1: card_id | C1: 职业 | D1: 卡牌名称 | E1: 名称_en | F1: 类别 | G1: 稀有度 | H1: 费用消耗 | I1: 费用_升级后 | J1: 效果原文 | K1: 效果解析 | L1: 目标类型 | M1: 伤害基础 | N1: 伤害升级 | O1: 伤害段数 | P1: 格挡基础 | Q1: 格挡升级 | R1: 抽牌数基础 | S1: 抽牌数升级 | T1: 弃牌数基础 | U1: 弃牌数升级 | V1: 获得能量值基础 | W1: 获得能量值升级 | X1: 获得星辉 | Y1: 获得星辉升级 | Z1: 给予虚弱层数基础 | AA1: 给予虚弱升级 | AB1: 给予易伤层数基础 | AC1: 给予易伤升级 | AD1: 生成状态牌 | AE1: 给予力量 | AF1: 给予中毒 | AG1: 给予灾厄 | AH1: 给予敏捷 | AI1: 给予集中 | AJ1: 给予覆甲 | AK1: 消耗类型 | AL1: 是否保留/持续 | AM1: 基础卡_id | AN1: 核心标签效果 | AO1: 计算备注 | AP1: 计算用等效费用 | AQ1: 临时升级牌数基础 | AR1: 临时升级牌数_升级 | AS1: 卡图 | AT1: 版本/数据源 | AU1: 召唤 | AY1: 产出价值/原牌效 | AZ1: 费用节奏修正牌效 | BA1: 产出每费效率
A2: 1 | B2: ironclad_strike | C2: 铁甲战士 | D2: 打击 | E2: Strike | F2: 攻击 | G2: 基础 | H2: 1 | I2: 1 | J2: 造成6点伤害。 | K2: 造成6伤害，无易伤。 | L2: enemy_single | M2: 6 | N2: 9 | O2: 1 | P2: 0 | Q2: 0 | R2: 0 | S2: 0 | T2: 0 | U2: 0 | V2: 0 | W2: 0 | X2: 0 | Y2: 0 | Z2: 0 | AA2: 0 | AB2: 0 | AC2: 0 | AD2: 0 | AE2: 0 | AF2: 0 | AG2: 0 | AH2: 0 | AI2: 0 | AJ2: 0 | AK2: none | AL2: 0 | AO2: 版本基于v0.110.1，部分能力卡不好评估 | AP2: =IF(ISNUMBER(H2),IF(AND(H2=0,V2=0,AK2="none"),0.4,IF(AK2="exhaust",MAX(H2-V2,0.4),IF(AK2="ethereal",MAX(H2-V2,0.4),MAX(H2-V2,0.4)))),IF(AND(AK2="exhaust",OR(H2="X",H2="∞")),0.4,IF(OR(H2="X",H2="∞"),0.4,0.4))) -> 1 | AQ2: 0 | AR2: 0 | AT2: v0.110.1 sts2.info | AU2: 0 | AY2: =IFERROR(MAX(IF(IF(AND(F2="能力",AL2="能力持续"),(参数!$B$2-1)*参数!$B$3,0)+M2*O2*参数!$B$5*IF(AND(F2="能力",AL2="能力持续"),参数!$B$2,1)+P2*参数!$B$6*IF(AND(F2="能力",AL2="能力持续"),参数!$B$2,1)+R2*参数!$B$7*IF(AND(F2="能力",AL2="能力持续"),参数!$B$2,1)+V2*参数!$B$8+IF(X2<0,X2*参数!$B$13,X2*参数!$B$39)+IF(AE2<0,AE2*参数!$B$13,AE2*参数!$B$12)*参数!$B$2+AQ2*参数!$B$15+AB2*参数!$B$11+AF2*参数!$B$40*参数!$B$2+AG2*参数!$B$44*参数!$B$2+AH2*参数!$B$6*参数!$B$2+AI2*参数!$B$39*参数!$B$2+AJ2*参数!$B$6*参数!$B$2+Z2*参数!$B$13-T2*参数!$B$14-AD2*参数!$B$13+IF(ISNUMBER(AU2),AU2*参数!$B$38,0)-AV2*参数!$B$41-AW2*参数!$B$14>参数!$B$17,参数!$B$17+SQRT(IF(AND(F2="能力",AL2="能力持续"),(参数!$B$2-1)*参数!$B$3,0)+M2*O2*参数!$B$5*IF(AND(F2="能力",AL2="能力持续"),参数!$B$2,1)+P2*参数!$B$6*IF(AND(F2="能力",AL2="能力持续"),参数!$B$2,1)+R2*参数!$B$7*IF(AND(F2="能力",AL2="能力持续"),参数!$B$2,1)+V2*参数!$B$8+IF(X2<0,X2*参数!$B$13,X2*参数!$B$39)+IF(AE2<0,AE2*参数!$B$13,AE2*参数!$B$12)*参数!$B$2+AQ2*参数!$B$15+AB2*参数!$B$11+AF2*参数!$B$40*参数!$B$2+AG2*参数!$B$44*参数!$B$2+AH2*参数!$B$6*参数!$B$2+AI2*参数!$B$39*参数!$B$2+AJ2*参数!$B$6*参数!$B$2+Z2*参数!$B$13-T2*参数!$B$14-AD2*参数!$B$13+IF(ISNUMBER(AU2),AU2*参数!$B$38,0)-AV2*参数!$B$41-AW2*参数!$B$14-参数!$B$17)*参数!$B$18,IF(AND(F2="能力",AL2="能力持续"),(参数!$B$2-1)*参数!$B$3,0)+M2*O2*参数!$B$5*IF(AND(F2="能力",AL2="能力持续"),参数!$B$2,1)+P2*参数!$B$6*IF(AND(F2="能力",AL2="能力持续"),参数!$B$2,1)+R2*参数!$B$7*IF(AND(F2="能力",AL2="能力持续"),参数!$B$2,1)+V2*参数!$B$8+IF(X2<0,X2*参数!$B$13,X2*参数!$B$39)+IF(AE2<0,AE2*参数!$B$13,AE2*参数!$B$12)*参数!$B$2+AQ2*参数!$B$15+AB2*参数!$B$11+AF2*参数!$B$40*参数!$B$2+AG2*参数!$B$44*参数!$B$2+AH2*参数!$B$6*参数!$B$2+AI2*参数!$B$39*参数!$B$2+AJ2*参数!$B$6*参数!$B$2+Z2*参数!$B$13-T2*参数!$B$14-AD2*参数!$B$13+IF(ISNUMBER(AU2),AU2*参数!$B$38,0)-AV2*参数!$B$41-AW2*参数!$B$14),0),0) -> 6 | AZ2: =AY2-MAX(AP2,0)*参数!$B$10 -> 3 | BA2: =IF(MAX(AP2,0)=0,AY2,AY2/MAX(AP2,0)) -> 6
A3: 2 | B3: ironclad_defend | C3: 铁甲战士 | D3: 防御 | E3: Defend | F3: 技能 | G3: 基础 | H3: 1 | I3: 1 | J3: 获得5点格挡。 | K3: 获得5格挡，无伤害。 | L3: self | M3: 0 | N3: 0 | O3: 1 | P3: 5 | Q3: 8 | R3: 0 | S3: 0 | T3: 0 | U3: 0 | V3: 0 | W3: 0 | X3: 0 | Y3: 0 | Z3: 0 | AA3: 0 | AB3: 0 | AC3: 0 | AD3: 0 | AE3: 0 | AF3: 0 | AG3: 0 | AH3: 0 | AI3: 0 | AJ3: 0 | AK3: none | AL3: 0 | AP3: =IF(ISNUMBER(H3),IF(AND(H3=0,V3=0,AK3="none"),0.4,IF(AK3="exhaust",MAX(H3-V3,0.4),IF(AK3="ethereal",MAX(H3-V3,0.4),MAX(H3-V3,0.4)))),IF(AND(AK3="exhaust",OR(H3="X",H3="∞")),0.4,IF(OR(H3="X",H3="∞"),0.4,0.4))) -> 1 | AQ3: 0 | AR3: 0 | AT3: v0.110.1 sts2.info | AU3: 0 | AY3: =IFERROR(MAX(IF(IF(AND(F3="能力",AL3="能力持续"),(参数!$B$2-1)*参数!$B$3,0)+M3*O3*参数!$B$5*IF(AND(F3="能力",AL3="能力持续"),参数!$B$2,1)+P3*参数!$B$6*IF(AND(F3="能力",AL3="能力持续"),参数!$B$2,1)+R3*参数!$B$7*IF(AND(F3="能力",AL3="能力持续"),参数!$B$2,1)+V3*参数!$B$8+IF(X3<0,X3*参数!$B$13,X3*参数!$B$39)+IF(AE3<0,AE3*参数!$B$13,AE3*参数!$B$12)*参数!$B$2+AQ3*参数!$B$15+AB3*参数!$B$11+AF3*参数!$B$40*参数!$B$2+AG3*参数!$B$44*参数!$B$2+AH3*参数!$B$6*参数!$B$2+AI3*参数!$B$39*参数!$B$2+AJ3*参数!$B$6*参数!$B$2+Z3*参数!$B$13-T3*参数!$B$14-AD3*参数!$B$13+IF(ISNUMBER(AU3),AU3*参数!$B$38,0)-AV3*参数!$B$41-AW3*参数!$B$14>参数!$B$17,参数!$B$17+SQRT(IF(AND(F3="能力",AL3="能力持续"),(参数!$B$2-1)*参数!$B$3,0)+M3*O3*参数!$B$5*IF(AND(F3="能力",AL3="能力持续"),参数!$B$2,1)+P3*参数!$B$6*IF(AND(F3="能力",AL3="能力持续"),参数!$B$2,1)+R3*参数!$B$7*IF(AND(F3="能力",AL3="能力持续"),参数!$B$2,1)+V3*参数!$B$8+IF(X3<0,X3*参数!$B$13,X3*参数!$B$39)+IF(AE3<0,AE3*参数!$B$13,AE3*参数!$B$12)*参数!$B$2+AQ3*参数!$B$15+AB3*参数!$B$11+AF3*参数!$B$40*参数!$B$2+AG3*参数!$B$44*参数!$B$2+AH3*参数!$B$6*参数!$B$2+AI3*参数!$B$39*参数!$B$2+AJ3*参数!$B$6*参数!$B$2+Z3*参数!$B$13-T3*参数!$B$14-AD3*参数!$B$13+IF(ISNUMBER(AU3),AU3*参数!$B$38,0)-AV3*参数!$B$41-AW3*参数!$B$14-参数!$B$17)*参数!$B$18,IF(AND(F3="能力",AL3="能力持续"),(参数!$B$2-1)*参数!$B$3,0)+M3*O3*参数!$B$5*IF(AND(F3="能力",AL3="能力持续"),参数!$B$2,1)+P3*参数!$B$6*IF(AND(F3="能力",AL3="能力持续"),参数!$B$2,1)+R3*参数!$B$7*IF(AND(F3="能力",AL3="能力持续"),参数!$B$2,1)+V3*参数!$B$8+IF(X3<0,X3*参数!$B$13,X3*参数!$B$39)+IF(AE3<0,AE3*参数!$B$13,AE3*参数!$B$12)*参数!$B$2+AQ3*参数!$B$15+AB3*参数!$B$11+AF3*参数!$B$40*参数!$B$2+AG3*参数!$B$44*参数!$B$2+AH3*参数!$B$6*参数!$B$2+AI3*参数!$B$39*参数!$B$2+AJ3*参数!$B$6*参数!$B$2+Z3*参数!$B$13-T3*参数!$B$14-AD3*参数!$B$13+IF(ISNUMBER(AU3),AU3*参数!$B$38,0)-AV3*参数!$B$41-AW3*参数!$B$14),0),0) -> 5.5 | AZ3: =AY3-MAX(AP3,0)*参数!$B$10 -> 2.5 | BA3: =IF(MAX(AP3,0)=0,AY3,AY3/MAX(AP3,0)) -> 5.5
A4: 3 | B4: ironclad_aggression | C4: 铁甲战士 | D4: 好勇斗狠 | E4: Aggression | F4: 能力 | G4: 稀有 | H4: 1 | I4: 1 | J4: 在你的回合开始时，将你弃牌堆的一张随机攻击牌放入你的手牌并将其升级。 | K4: 弃牌堆拿一张攻击牌，升级该牌。 | L4: self | M4: 0 | N4: 0 | O4: 1 | P4: 0 | Q4: 0 | R4: 0 | S4: 0 | T4: 0 | U4: 0 | V4: 0 | W4: 0 | X4: 0 | Y4: 0 | Z4: 0 | AA4: 0 | AB4: 0 | AC4: 0 | AD4: 0 | AE4: 0 | AF4: 0 | AG4: 0 | AH4: 0 | AI4: 0 | AJ4: 0 | AK4: none | AL4: 能力持续 | AN4: 能力，固有，弃牌回收，临时升级 | AO4: 此卡是敲后固有 | AP4: =IF(ISNUMBER(H4),IF(AND(H4=0,V4=0,AK4="none"),0.4,IF(AK4="exhaust",MAX(H4-V4,0.4),IF(AK4="ethereal",MAX(H4-V4,0.4),MAX(H4-V4,0.4)))),IF(AND(AK4="exhaust",OR(H4="X",H4="∞")),0.4,IF(OR(H4="X",H4="∞"),0.4,0.4))) -> 1 | AQ4: 0 | AR4: 0 | AT4: v0.110.1 sts2.info | AU4: 0 | AY4: =IFERROR(MAX(IF(IF(AND(F4="能力",AL4="能力持续"),(参数!$B$2-1)*参数!$B$3,0)+M4*O4*参数!$B$5*IF(AND(F4="能力",AL4="能力持续"),参数!$B$2,1)+P4*参数!$B$6*IF(AND(F4="能力",AL4="能力持续"),参数!$B$2,1)+R4*参数!$B$7*IF(AND(F4="能力",AL4="能力持续"),参数!$B$2,1)+V4*参数!$B$8+IF(X4<0,X4*参数!$B$13,X4*参数!$B$39)+IF(AE4<0,AE4*参数!$B$13,AE4*参数!$B$12)*参数!$B$2+AQ4*参数!$B$15+AB4*参数!$B$11+AF4*参数!$B$40*参数!$B$2+AG4*参数!$B$44*参数!$B$2+AH4*参数!$B$6*参数!$B$2+AI4*参数!$B$39*参数!$B$2+AJ4*参数!$B$6*参数!$B$2+Z4*参数!$B$13-T4*参数!$B$14-AD4*参数!$B$13+IF(ISNUMBER(AU4),AU4*参数!$B$38,0)-AV4*参数!$B$41-AW4*参数!$B$14>参数!$B$17,参数!$B$17+SQRT(IF(AND(F4="能力",AL4="能力持续"),(参数!$B$2-1)*参数!$B$3,0)+M4*O4*参数!$B$5*IF(AND(F4="能力",AL4="能力持续"),参数!$B$2,1)+P4*参数!$B$6*IF(AND(F4="能力",AL4="能力持续"),参数!$B$2,1)+R4*参数!$B$7*IF(AND(F4="能力",AL4="能力持续"),参数!$B$2,1)+V4*参数!$B$8+IF(X4<0,X4*参数!$B$13,X4*参数!$B$39)+IF(AE4<0,AE4*参数!$B$13,AE4*参数!$B$12)*参数!$B$2+AQ4*参数!$B$15+AB4*参数!$B$11+AF4*参数!$B$40*参数!$B$2+AG4*参数!$B$44*参数!$B$2+AH4*参数!$B$6*参数!$B$2+AI4*参数!$B$39*参数!$B$2+AJ4*参数!$B$6*参数!$B$2+Z4*参数!$B$13-T4*参数!$B$14-AD4*参数!$B$13+IF(ISNUMBER(AU4),AU4*参数!$B$38,0)-AV4*参数!$B$41-AW4*参数!$B$14-参数!$B$17)*参数!$B$18,IF(AND(F4="能力",AL4="能力持续"),(参数!$B$2-1)*参数!$B$3,0)+M4*O4*参数!$B$5*IF(AND(F4="能力",AL4="能力持续"),参数!$B$2,1)+P4*参数!$B$6*IF(AND(F4="能力",AL4="能力持续"),参数!$B$2,1)+R4*参数!$B$7*IF(AND(F4="能力",AL4="能力持续"),参数!$B$2,1)+V4*参数!$B$8+IF(X4<0,X4*参数!$B$13,X4*参数!$B$39)+IF(AE4<0,AE4*参数!$B$13,AE4*参数!$B$12)*参数!$B$2+AQ4*参数!$B$15+AB4*参数!$B$11+AF4*参数!$B$40*参数!$B$2+AG4*参数!$B$44*参数!$B$2+AH4*参数!$B$6*参数!$B$2+AI4*参数!$B$39*参数!$B$2+AJ4*参数!$B$6*参数!$B$2+Z4*参数!$B$13-T4*参数!$B$14-AD4*参数!$B$13+IF(ISNUMBER(AU4),AU4*参数!$B$38,0)-AV4*参数!$B$41-AW4*参数!$B$14),0),0) -> 3.6 | AZ4: =AY4-MAX(AP4,0)*参数!$B$10 -> 0.6 | BA4: =IF(MAX(AP4,0)=0,AY4,AY4/MAX(AP4,0)) -> 3.6
A5: 4 | B5: ironclad_anger | C5: 铁甲战士 | D5: 愤怒 | E5: Anger | F5: 攻击 | G5: 普通 | H5: 0 | I5: 0 | J5: 造成6点伤害。 将一张此牌的复制品加入你的弃牌堆。 | K5: 生成一张同样的牌，造成6伤害 | L5: enermy_single | M5: 6 | N5: 8 | O5: 1 | P5: 0 | Q5: 0 | R5: 0 | S5: 0 | T5: 0 | U5: 0 | V5: 0 | W5: 0 | X5: 0 | Y5: 0 | Z5: 0 | AA5: 0 | AB5: 0 | AC5: 0 | AD5: 0 | AE5: 0 | AF5: 0 | AG5: 0 | AH5: 0 | AI5: 0 | AJ5: 0 | AK5: none | AL5: 0 | AP5: =IF(ISNUMBER(H5),IF(AND(H5=0,V5=0,AK5="none"),0.4,IF(AK5="exhaust",MAX(H5-V5,0.4),IF(AK5="ethereal",MAX(H5-V5,0.4),MAX(H5-V5,0.4)))),IF(AND(AK5="exhaust",OR(H5="X",H5="∞")),0.4,IF(OR(H5="X",H5="∞"),0.4,0.4))) -> 0.4 | AQ5: 0 | AR5: 0 | AT5: v0.110.1 sts2.info | AU5: 0 | AY5: =IFERROR(MAX(IF(IF(AND(F5="能力",AL5="能力持续"),(参数!$B$2-1)*参数!$B$3,0)+M5*O5*参数!$B$5*IF(AND(F5="能力",AL5="能力持续"),参数!$B$2,1)+P5*参数!$B$6*IF(AND(F5="能力",AL5="能力持续"),参数!$B$2,1)+R5*参数!$B$7*IF(AND(F5="能力",AL5="能力持续"),参数!$B$2,1)+V5*参数!$B$8+IF(X5<0,X5*参数!$B$13,X5*参数!$B$39)+IF(AE5<0,AE5*参数!$B$13,AE5*参数!$B$12)*参数!$B$2+AQ5*参数!$B$15+AB5*参数!$B$11+AF5*参数!$B$40*参数!$B$2+AG5*参数!$B$44*参数!$B$2+AH5*参数!$B$6*参数!$B$2+AI5*参数!$B$39*参数!$B$2+AJ5*参数!$B$6*参数!$B$2+Z5*参数!$B$13-T5*参数!$B$14-AD5*参数!$B$13+IF(ISNUMBER(AU5),AU5*参数!$B$38,0)-AV5*参数!$B$41-AW5*参数!$B$14>参数!$B$17,参数!$B$17+SQRT(IF(AND(F5="能力",AL5="能力持续"),(参数!$B$2-1)*参数!$B$3,0)+M5*O5*参数!$B$5*IF(AND(F5="能力",AL5="能力持续"),参数!$B$2,1)+P5*参数!$B$6*IF(AND(F5="能力",AL5="能力持续"),参数!$B$2,1)+R5*参数!$B$7*IF(AND(F5="能力",AL5="能力持续"),参数!$B$2,1)+V5*参数!$B$8+IF(X5<0,X5*参数!$B$13,X5*参数!$B$39)+IF(AE5<0,AE5*参数!$B$13,AE5*参数!$B$12)*参数!$B$2+AQ5*参数!$B$15+AB5*参数!$B$11+AF5*参数!$B$40*参数!$B$2+AG5*参数!$B$44*参数!$B$2+AH5*参数!$B$6*参数!$B$2+AI5*参数!$B$39*参数!$B$2+AJ5*参数!$B$6*参数!$B$2+Z5*参数!$B$13-T5*参数!$B$14-AD5*参数!$B$13+IF(ISNUMBER(AU5),AU5*参数!$B$38,0)-AV5*参数!$B$41-AW5*参数!$B$14-参数!$B$17)*参数!$B$18,IF(AND(F5="能力",AL5="能力持续"),(参数!$B$2-1)*参数!$B$3,0)+M5*O5*参数!$B$5*IF(AND(F5="能力",AL5="能力持续"),参数!$B$2,1)+P5*参数!$B$6*IF(AND(F5="能力",AL5="能力持续"),参数!$B$2,1)+R5*参数!$B$7*IF(AND(F5="能力",AL5="能力持续"),参数!$B$2,1)+V5*参数!$B$8+IF(X5<0,X5*参数!$B$13,X5*参数!$B$39)+IF(AE5<0,AE5*参数!$B$13,AE5*参数!$B$12)*参数!$B$2+AQ5*参数!$B$15+AB5*参数!$B$11+AF5*参数!$B$40*参数!$B$2+AG5*参数!$B$44*参数!$B$2+AH5*参数!$B$6*参数!$B$2+AI5*参数!$B$39*参数!$B$2+AJ5*参数!$B$6*参数!$B$2+Z5*参数!$B$13-T5*参数!$B$14-AD5*参数!$B$13+IF(ISNUMBER(AU5),AU5*参数!$B$38,0)-AV5*参数!$B$41-AW5*参数!$B$14),0),0) -> 6 | AZ5: =AY5-MAX(AP5,0)*参数!$B$10 -> 4.8 | BA5: =IF(MAX(AP5,0)=0,AY5,AY5/MAX(AP5,0)) -> 15
A6: 5 | B6: ironclad_armaments | C6: 铁甲战士 | D6: 武装 | E6: Armaments | F6: 技能 | G6: 普通 | H6: 1 | I6: 1 | J6: 获得5点格挡。 升级你手牌中的一张牌。 | K6: 升级一张牌，防御5 | L6: self | M6: 0 | N6: 0 | O6: 1 | P6: 5 | Q6: 5 | R6: 0 | S6: 0 | T6: 0 | U6: 0 | V6: 0 | W6: 0 | X6: 0 | Y6: 0 | Z6: 0 | AA6: 0 | AB6: 0 | AC6: 0 | AD6: 0 | AE6: 0 | AF6: 0 | AG6: 0 | AH6: 0 | AI6: 0 | AJ6: 0 | AK6: none | AL6: 0 | AP6: =IF(ISNUMBER(H6),IF(AND(H6=0,V6=0,AK6="none"),0.4,IF(AK6="exhaust",MAX(H6-V6,0.4),IF(AK6="ethereal",MAX(H6-V6,0.4),MAX(H6-V6,0.4)))),IF(AND(AK6="exhaust",OR(H6="X",H6="∞")),0.4,IF(OR(H6="X",H6="∞"),0.4,0.4))) -> 1 | AQ6: 0 | AR6: 0 | AT6: v0.110.1 sts2.info | AU6: 0 | AY6: =IFERROR(MAX(IF(IF(AND(F6="能力",AL6="能力持续"),(参数!$B$2-1)*参数!$B$3,0)+M6*O6*参数!$B$5*IF(AND(F6="能力",AL6="能力持续"),参数!$B$2,1)+P6*参数!$B$6*IF(AND(F6="能力",AL6="能力持续"),参数!$B$2,1)+R6*参数!$B$7*IF(AND(F6="能力",AL6="能力持续"),参数!$B$2,1)+V6*参数!$B$8+IF(X6<0,X6*参数!$B$13,X6*参数!$B$39)+IF(AE6<0,AE6*参数!$B$13,AE6*参数!$B$12)*参数!$B$2+AQ6*参数!$B$15+AB6*参数!$B$11+AF6*参数!$B$40*参数!$B$2+AG6*参数!$B$44*参数!$B$2+AH6*参数!$B$6*参数!$B$2+AI6*参数!$B$39*参数!$B$2+AJ6*参数!$B$6*参数!$B$2+Z6*参数!$B$13-T6*参数!$B$14-AD6*参数!$B$13+IF(ISNUMBER(AU6),AU6*参数!$B$38,0)-AV6*参数!$B$41-AW6*参数!$B$14>参数!$B$17,参数!$B$17+SQRT(IF(AND(F6="能力",AL6="能力持续"),(参数!$B$2-1)*参数!$B$3,0)+M6*O6*参数!$B$5*IF(AND(F6="能力",AL6="能力持续"),参数!$B$2,1)+P6*参数!$B$6*IF(AND(F6="能力",AL6="能力持续"),参数!$B$2,1)+R6*参数!$B$7*IF(AND(F6="能力",AL6="能力持续"),参数!$B$2,1)+V6*参数!$B$8+IF(X6<0,X6*参数!$B$13,X6*参数!$B$39)+IF(AE6<0,AE6*参数!$B$13,AE6*参数!$B$12)*参数!$B$2+AQ6*参数!$B$15+AB6*参数!$B$11+AF6*参数!$B$40*参数!$B$2+AG6*参数!$B$44*参数!$B$2+AH6*参数!$B$6*参数!$B$2+AI6*参数!$B$39*参数!$B$2+AJ6*参数!$B$6*参数!$B$2+Z6*参数!$B$13-T6*参数!$B$14-AD6*参数!$B$13+IF(ISNUMBER(AU6),AU6*参数!$B$38,0)-AV6*参数!$B$41-AW6*参数!$B$14-参数!$B$17)*参数!$B$18,IF(AND(F6="能力",AL6="能力持续"),(参数!$B$2-1)*参数!$B$3,0)+M6*O6*参数!$B$5*IF(AND(F6="能力",AL6="能力持续"),参数!$B$2,1)+P6*参数!$B$6*IF(AND(F6="能力",AL6="能力持续"),参数!$B$2,1)+R6*参数!$B$7*IF(AND(F6="能力",AL6="能力持续"),参数!$B$2,1)+V6*参数!$B$8+IF(X6<0,X6*参数!$B$13,X6*参数!$B$39)+IF(AE6<0,AE6*参数!$B$13,AE6*参数!$B$12)*参数!$B$2+AQ6*参数!$B$15+AB6*参数!$B$11+AF6*参数!$B$40*参数!$B$2+AG6*参数!$B$44*参数!$B$2+AH6*参数!$B$6*参数!$B$2+AI6*参数!$B$39*参数!$B$2+AJ6*参数!$B$6*参数!$B$2+Z6*参数!$B$13-T6*参数!$B$14-AD6*参数!$B$13+IF(ISNUMBER(AU6),AU6*参数!$B$38,0)-AV6*参数!$B$41-AW6*参数!$B$14),0),0) -> 5.5 | AZ6: =AY6-MAX(AP6,0)*参数!$B$10 -> 2.5 | BA6: =IF(MAX(AP6,0)=0,AY6,AY6/MAX(AP6,0)) -> 5.5
A7: 6 | B7: ironclad_ashen_strike | C7: 铁甲战士 | D7: 灰烬打击 | E7: Ashen Strike | F7: 攻击 | G7: 罕见 | H7: 1 | I7: 1 | J7: 造成6点伤害。 你的消耗牌堆中每有一张牌，伤害增加3。 | K7: 攻击终端卡，打出3x+6的伤害 | L7: enemy_single | M7: =6+参数!$B$42*3 -> 24 | N7: 6 | O7: 1 | P7: 0 | Q7: 0 | R7: 0 | S7: 0 | T7: 0 | U7: 0 | V7: 0 | W7: 0 | X7: 0 | Y7: 0 | Z7: 0 | AA7: 0 | AB7: 0 | AC7: 0 | AD7: 0 | AE7: 0 | AF7: 0 | AG7: 0 | AH7: 0 | AI7: 0 | AJ7: 0 | AK7: none | AL7: 0 | AO7: 加伤效果视为打击多次升级 | AP7: =IF(ISNUMBER(H7),IF(AND(H7=0,V7=0,AK7="none"),0.4,IF(AK7="exhaust",MAX(H7-V7,0.4),IF(AK7="ethereal",MAX(H7-V7,0.4),MAX(H7-V7,0.4)))),IF(AND(AK7="exhaust",OR(H7="X",H7="∞")),0.4,IF(OR(H7="X",H7="∞"),0.4,0.4))) -> 1 | AQ7: 0 | AR7: 0 | AT7: v0.110.1 sts2.info | AU7: 0 | AY7: =IFERROR(MAX(IF(IF(AND(F7="能力",AL7="能力持续"),(参数!$B$2-1)*参数!$B$3,0)+M7*O7*参数!$B$5*IF(AND(F7="能力",AL7="能力持续"),参数!$B$2,1)+P7*参数!$B$6*IF(AND(F7="能力",AL7="能力持续"),参数!$B$2,1)+R7*参数!$B$7*IF(AND(F7="能力",AL7="能力持续"),参数!$B$2,1)+V7*参数!$B$8+IF(X7<0,X7*参数!$B$13,X7*参数!$B$39)+IF(AE7<0,AE7*参数!$B$13,AE7*参数!$B$12)*参数!$B$2+AQ7*参数!$B$15+AB7*参数!$B$11+AF7*参数!$B$40*参数!$B$2+AG7*参数!$B$44*参数!$B$2+AH7*参数!$B$6*参数!$B$2+AI7*参数!$B$39*参数!$B$2+AJ7*参数!$B$6*参数!$B$2+Z7*参数!$B$13-T7*参数!$B$14-AD7*参数!$B$13+IF(ISNUMBER(AU7),AU7*参数!$B$38,0)-AV7*参数!$B$41-AW7*参数!$B$14>参数!$B$17,参数!$B$17+SQRT(IF(AND(F7="能力",AL7="能力持续"),(参数!$B$2-1)*参数!$B$3,0)+M7*O7*参数!$B$5*IF(AND(F7="能力",AL7="能力持续"),参数!$B$2,1)+P7*参数!$B$6*IF(AND(F7="能力",AL7="能力持续"),参数!$B$2,1)+R7*参数!$B$7*IF(AND(F7="能力",AL7="能力持续"),参数!$B$2,1)+V7*参数!$B$8+IF(X7<0,X7*参数!$B$13,X7*参数!$B$39)+IF(AE7<0,AE7*参数!$B$13,AE7*参数!$B$12)*参数!$B$2+AQ7*参数!$B$15+AB7*参数!$B$11+AF7*参数!$B$40*参数!$B$2+AG7*参数!$B$44*参数!$B$2+AH7*参数!$B$6*参数!$B$2+AI7*参数!$B$39*参数!$B$2+AJ7*参数!$B$6*参数!$B$2+Z7*参数!$B$13-T7*参数!$B$14-AD7*参数!$B$13+IF(ISNUMBER(AU7),AU7*参数!$B$38,0)-AV7*参数!$B$41-AW7*参数!$B$14-参数!$B$17)*参数!$B$18,IF(AND(F7="能力",AL7="能力持续"),(参数!$B$2-1)*参数!$B$3,0)+M7*O7*参数!$B$5*IF(AND(F7="能力",AL7="能力持续"),参数!$B$2,1)+P7*参数!$B$6*IF(AND(F7="能力",AL7="能力持续"),参数!$B$2,1)+R7*参数!$B$7*IF(AND(F7="能力",AL7="能力持续"),参数!$B$2,1)+V7*参数!$B$8+IF(X7<0,X7*参数!$B$13,X7*参数!$B$39)+IF(AE7<0,AE7*参数!$B$13,AE7*参数!$B$12)*参数!$B$2+AQ7*参数!$B$15+AB7*参数!$B$11+AF7*参数!$B$40*参数!$B$2+AG7*参数!$B$44*参数!$B$2+AH7*参数!$B$6*参数!$B$2+AI7*参数!$B$39*参数!$B$2+AJ7*参数!$B$6*参数!$B$2+Z7*参数!$B$13-T7*参数!$B$14-AD7*参数!$B$13+IF(ISNUMBER(AU7),AU7*参数!$B$38,0)-AV7*参数!$B$41-AW7*参数!$B$14),0),0) -> 15.612486 | AZ7: =AY7-MAX(AP7,0)*参数!$B$10 -> 12.612486 | BA7: =IF(MAX(AP7,0)=0,AY7,AY7/MAX(AP7,0)) -> 15.612486
A8: 7 | B8: ironclad_barricade | C8: 铁甲战士 | D8: 壁垒 | E8: Barricade | F8: 能力 | G8: 稀有 | H8: 3 | I8: 2 | J8: 格挡不再在你的回合开始时消失。 | K8: 保留防御值 | L8: self | M8: 0 | N8: 0 | O8: 1 | P8: 0 | Q8: 0 | R8: 0 | S8: 0 | T8: 0 | U8: 0 | V8: 0 | W8: 0 | X8: 0 | Y8: 0 | Z8: 0 | AA8: 0 | AB8: 0 | AC8: 0 | AD8: 0 | AE8: 0 | AF8: 0 | AG8: 0 | AH8: 0 | AI8: 0 | AJ8: 0 | AK8: none | AL8: 能力持续 | AO8: 保留格挡视为防御多次升级乘以能力系数 | AP8: =IF(ISNUMBER(H8),IF(AND(H8=0,V8=0,AK8="none"),0.4,IF(AK8="exhaust",MAX(H8-V8,0.4),IF(AK8="ethereal",MAX(H8-V8,0.4),MAX(H8-V8,0.4)))),IF(AND(AK8="exhaust",OR(H8="X",H8="∞")),0.4,IF(OR(H8="X",H8="∞"),0.4,0.4))) -> 3 | AQ8: 0 | AR8: 0 | AT8: v0.110.1 sts2.info | AU8: 0 | AY8: =IFERROR(MAX(IF(IF(AND(F8="能力",AL8="能力持续"),(参数!$B$2-1)*参数!$B$3,0)+M8*O8*参数!$B$5*IF(AND(F8="能力",AL8="能力持续"),参数!$B$2,1)+P8*参数!$B$6*IF(AND(F8="能力",AL8="能力持续"),参数!$B$2,1)+R8*参数!$B$7*IF(AND(F8="能力",AL8="能力持续"),参数!$B$2,1)+V8*参数!$B$8+IF(X8<0,X8*参数!$B$13,X8*参数!$B$39)+IF(AE8<0,AE8*参数!$B$13,AE8*参数!$B$12)*参数!$B$2+AQ8*参数!$B$15+AB8*参数!$B$11+AF8*参数!$B$40*参数!$B$2+AG8*参数!$B$44*参数!$B$2+AH8*参数!$B$6*参数!$B$2+AI8*参数!$B$39*参数!$B$2+AJ8*参数!$B$6*参数!$B$2+Z8*参数!$B$13-T8*参数!$B$14-AD8*参数!$B$13+IF(ISNUMBER(AU8),AU8*参数!$B$38,0)-AV8*参数!$B$41-AW8*参数!$B$14>参数!$B$17,参数!$B$17+SQRT(IF(AND(F8="能力",AL8="能力持续"),(参数!$B$2-1)*参数!$B$3,0)+M8*O8*参数!$B$5*IF(AND(F8="能力",AL8="能力持续"),参数!$B$2,1)+P8*参数!$B$6*IF(AND(F8="能力",AL8="能力持续"),参数!$B$2,1)+R8*参数!$B$7*IF(AND(F8="能力",AL8="能力持续"),参数!$B$2,1)+V8*参数!$B$8+IF(X8<0,X8*参数!$B$13,X8*参数!$B$39)+IF(AE8<0,AE8*参数!$B$13,AE8*参数!$B$12)*参数!$B$2+AQ8*参数!$B$15+AB8*参数!$B$11+AF8*参数!$B$40*参数!$B$2+AG8*参数!$B$44*参数!$B$2+AH8*参数!$B$6*参数!$B$2+AI8*参数!$B$39*参数!$B$2+AJ8*参数!$B$6*参数!$B$2+Z8*参数!$B$13-T8*参数!$B$14-AD8*参数!$B$13+IF(ISNUMBER(AU8),AU8*参数!$B$38,0)-AV8*参数!$B$41-AW8*参数!$B$14-参数!$B$17)*参数!$B$18,IF(AND(F8="能力",AL8="能力持续"),(参数!$B$2-1)*参数!$B$3,0)+M8*O8*参数!$B$5*IF(AND(F8="能力",AL8="能力持续"),参数!$B$2,1)+P8*参数!$B$6*IF(AND(F8="能力",AL8="能力持续"),参数!$B$2,1)+R8*参数!$B$7*IF(AND(F8="能力",AL8="能力持续"),参数!$B$2,1)+V8*参数!$B$8+IF(X8<0,X8*参数!$B$13,X8*参数!$B$39)+IF(AE8<0,AE8*参数!$B$13,AE8*参数!$B$12)*参数!$B$2+AQ8*参数!$B$15+AB8*参数!$B$11+AF8*参数!$B$40*参数!$B$2+AG8*参数!$B$44*参数!$B$2+AH8*参数!$B$6*参数!$B$2+AI8*参数!$B$39*参数!$B$2+AJ8*参数!$B$6*参数!$B$2+Z8*参数!$B$13-T8*参数!$B$14-AD8*参数!$B$13+IF(ISNUMBER(AU8),AU8*参数!$B$38,0)-AV8*参数!$B$41-AW8*参数!$B$14),0),0) -> 3.6 | AZ8: =AY8-MAX(AP8,0)*参数!$B$10 -> -5.4 | BA8: =IF(MAX(AP8,0)=0,AY8,AY8/MAX(AP8,0)) -> 1.2
A9: 8 | B9: ironclad_bash | C9: 铁甲战士 | D9: 痛击 | E9: Bash | F9: 攻击 | G9: 基础 | H9: 2 | I9: 2 | J9: 造成8点伤害。 给予2层易伤。 | K9: 造成8伤害，给予2易伤 | L9: enemy_single | M9: 8 | N9: 10 | O9: 1 | P9: 0 | Q9: 0 | R9: 0 | S9: 0 | T9: 0 | U9: 0 | V9: 0 | W9: 0 | X9: 0 | Y9: 0 | Z9: 0 | AA9: 2 | AB9: 2 | AC9: 3 | AD9: 0 | AE9: 0 | AF9: 0 | AG9: 0 | AH9: 0 | AI9: 0 | AJ9: 0 | AK9: none | AL9: 0 | AP9: =IF(ISNUMBER(H9),IF(AND(H9=0,V9=0,AK9="none"),0.4,IF(AK9="exhaust",MAX(H9-V9,0.4),IF(AK9="ethereal",MAX(H9-V9,0.4),MAX(H9-V9,0.4)))),IF(AND(AK9="exhaust",OR(H9="X",H9="∞")),0.4,IF(OR(H9="X",H9="∞"),0.4,0.4))) -> 2 | AQ9: 0 | AR9: 0 | AT9: v0.110.1 sts2.info | AU9: 0 | AV9: 2 | AY9: =IFERROR(MAX(IF(IF(AND(F9="能力",AL9="能力持续"),(参数!$B$2-1)*参数!$B$3,0)+M9*O9*参数!$B$5*IF(AND(F9="能力",AL9="能力持续"),参数!$B$2,1)+P9*参数!$B$6*IF(AND(F9="能力",AL9="能力持续"),参数!$B$2,1)+R9*参数!$B$7*IF(AND(F9="能力",AL9="能力持续"),参数!$B$2,1)+V9*参数!$B$8+IF(X9<0,X9*参数!$B$13,X9*参数!$B$39)+IF(AE9<0,AE9*参数!$B$13,AE9*参数!$B$12)*参数!$B$2+AQ9*参数!$B$15+AB9*参数!$B$11+AF9*参数!$B$40*参数!$B$2+AG9*参数!$B$44*参数!$B$2+AH9*参数!$B$6*参数!$B$2+AI9*参数!$B$39*参数!$B$2+AJ9*参数!$B$6*参数!$B$2+Z9*参数!$B$13-T9*参数!$B$14-AD9*参数!$B$13+IF(ISNUMBER(AU9),AU9*参数!$B$38,0)-AV9*参数!$B$41-AW9*参数!$B$14>参数!$B$17,参数!$B$17+SQRT(IF(AND(F9="能力",AL9="能力持续"),(参数!$B$2-1)*参数!$B$3,0)+M9*O9*参数!$B$5*IF(AND(F9="能力",AL9="能力持续"),参数!$B$2,1)+P9*参数!$B$6*IF(AND(F9="能力",AL9="能力持续"),参数!$B$2,1)+R9*参数!$B$7*IF(AND(F9="能力",AL9="能力持续"),参数!$B$2,1)+V9*参数!$B$8+IF(X9<0,X9*参数!$B$13,X9*参数!$B$39)+IF(AE9<0,AE9*参数!$B$13,AE9*参数!$B$12)*参数!$B$2+AQ9*参数!$B$15+AB9*参数!$B$11+AF9*参数!$B$40*参数!$B$2+AG9*参数!$B$44*参数!$B$2+AH9*参数!$B$6*参数!$B$2+AI9*参数!$B$39*参数!$B$2+AJ9*参数!$B$6*参数!$B$2+Z9*参数!$B$13-T9*参数!$B$14-AD9*参数!$B$13+IF(ISNUMBER(AU9),AU9*参数!$B$38,0)-AV9*参数!$B$41-AW9*参数!$B$14-参数!$B$17)*参数!$B$18,IF(AND(F9="能力",AL9="能力持续"),(参数!$B$2-1)*参数!$B$3,0)+M9*O9*参数!$B$5*IF(AND(F9="能力",AL9="能力持续"),参数!$B$2,1)+P9*参数!$B$6*IF(AND(F9="能力",AL9="能力持续"),参数!$B$2,1)+R9*参数!$B$7*IF(AND(F9="能力",AL9="能力持续"),参数!$B$2,1)+V9*参数!$B$8+IF(X9<0,X9*参数!$B$13,X9*参数!$B$39)+IF(AE9<0,AE9*参数!$B$13,AE9*参数!$B$12)*参数!$B$2+AQ9*参数!$B$15+AB9*参数!$B$11+AF9*参数!$B$40*参数!$B$2+AG9*参数!$B$44*参数!$B$2+AH9*参数!$B$6*参数!$B$2+AI9*参数!$B$39*参数!$B$2+AJ9*参数!$B$6*参数!$B$2+Z9*参数!$B$13-T9*参数!$B$14-AD9*参数!$B$13+IF(ISNUMBER(AU9),AU9*参数!$B$38,0)-AV9*参数!$B$41-AW9*参数!$B$14),0),0) -> 4.6 | AZ9: =AY9-MAX(AP9,0)*参数!$B$10 -> -1.4 | BA9: =IF(MAX(AP9,0)=0,AY9,AY9/MAX(AP9,0)) -> 2.3
A10: 9 | B10: ironclad_battle_trance | C10: 铁甲战士 | D10: 战斗专注 | E10: Battle Trance | F10: 技能 | G10: 罕见 | H10: 0 | I10: 0 | J10: 抽3张牌。 你在本回合内不能再抽任何牌。 | L10: enemy_single | M10: 0 | N10: 0 | O10: 1 | P10: 0 | Q10: 0 | R10: 3 | S10: 4 | T10: 0 | U10: 0 | V10: 0 | W10: 0 | X10: 0 | Y10: 0 | Z10: 0 | AA10: 0 | AB10: 0 | AC10: 0 | AD10: 0 | AE10: 0 | AF10: 0 | AG10: 0 | AH10: 0 | AI10: 0 | AJ10: 0 | AK10: none | AN10: 本回合 | AP10: =IF(ISNUMBER(H10),IF(AND(H10=0,V10=0,AK10="none"),0.4,IF(AK10="exhaust",MAX(H10-V10,0.4),IF(AK10="ethereal",MAX(H10-V10,0.4),MAX(H10-V10,0.4)))),IF(AND(AK10="exhaust",OR(H10="X",H10="∞")),0.4,IF(OR(H10="X",H10="∞"),0.4,0.4))) -> 0.4 | AQ10: 0 | AR10: 0 | AT10: v0.110.1 sts2.info | AU10: 0 | AY10: =IFERROR(MAX(IF(IF(AND(F10="能力",AL10="能力持续"),(参数!$B$2-1)*参数!$B$3,0)+M10*O10*参数!$B$5*IF(AND(F10="能力",AL10="能力持续"),参数!$B$2,1)+P10*参数!$B$6*IF(AND(F10="能力",AL10="能力持续"),参数!$B$2,1)+R10*参数!$B$7*IF(AND(F10="能力",AL10="能力持续"),参数!$B$2,1)+V10*参数!$B$8+IF(X10<0,X10*参数!$B$13,X10*参数!$B$39)+IF(AE10<0,AE10*参数!$B$13,AE10*参数!$B$12)*参数!$B$2+AQ10*参数!$B$15+AB10*参数!$B$11+AF10*参数!$B$40*参数!$B$2+AG10*参数!$B$44*参数!$B$2+AH10*参数!$B$6*参数!$B$2+AI10*参数!$B$39*参数!$B$2+AJ10*参数!$B$6*参数!$B$2+Z10*参数!$B$13-T10*参数!$B$14-AD10*参数!$B$13+IF(ISNUMBER(AU10),AU10*参数!$B$38,0)-AV10*参数!$B$41-AW10*参数!$B$14>参数!$B$17,参数!$B$17+SQRT(IF(AND(F10="能力",AL10="能力持续"),(参数!$B$2-1)*参数!$B$3,0)+M10*O10*参数!$B$5*IF(AND(F10="能力",AL10="能力持续"),参数!$B$2,1)+P10*参数!$B$6*IF(AND(F10="能力",AL10="能力持续"),参数!$B$2,1)+R10*参数!$B$7*IF(AND(F10="能力",AL10="能力持续"),参数!$B$2,1)+V10*参数!$B$8+IF(X10<0,X10*参数!$B$13,X10*参数!$B$39)+IF(AE10<0,AE10*参数!$B$13,AE10*参数!$B$12)*参数!$B$2+AQ10*参数!$B$15+AB10*参数!$B$11+AF10*参数!$B$40*参数!$B$2+AG10*参数!$B$44*参数!$B$2+AH10*参数!$B$6*参数!$B$2+AI10*参数!$B$39*参数!$B$2+AJ10*参数!$B$6*参数!$B$2+Z10*参数!$B$13-T10*参数!$B$14-AD10*参数!$B$13+IF(ISNUMBER(AU10),AU10*参数!$B$38,0)-AV10*参数!$B$41-AW10*参数!$B$14-参数!$B$17)*参数!$B$18,IF(AND(F10="能力",AL10="能力持续"),(参数!$B$2-1)*参数!$B$3,0)+M10*O10*参数!$B$5*IF(AND(F10="能力",AL10="能力持续"),参数!$B$2,1)+P10*参数!$B$6*IF(AND(F10="能力",AL10="能力持续"),参数!$B$2,1)+R10*参数!$B$7*IF(AND(F10="能力",AL10="能力持续"),参数!$B$2,1)+V10*参数!$B$8+IF(X10<0,X10*参数!$B$13,X10*参数!$B$39)+IF(AE10<0,AE10*参数!$B$13,AE10*参数!$B$12)*参数!$B$2+AQ10*参数!$B$15+AB10*参数!$B$11+AF10*参数!$B$40*参数!$B$2+AG10*参数!$B$44*参数!$B$2+AH10*参数!$B$6*参数!$B$2+AI10*参数!$B$39*参数!$B$2+AJ10*参数!$B$6*参数!$B$2+Z10*参数!$B$13-T10*参数!$B$14-AD10*参数!$B$13+IF(ISNUMBER(AU10),AU10*参数!$B$38,0)-AV10*参数!$B$41-AW10*参数!$B$14),0),0) -> 2.1 | AZ10: =AY10-MAX(AP10,0)*参数!$B$10 -> 0.9 | BA10: =IF(MAX(AP10,0)=0,AY10,AY10/MAX(AP10,0)) -> 5.25
A11: 10 | B11: ironclad_blood_wall | C11: 铁甲战士 | D11: 血墙 | E11: Blood Wall | F11: 技能 | G11: 普通 | H11: 2 | I11: 2 | J11: 失去2点生命。 获得16点格挡。 | L11: self | M11: 0 | N11: 0 | O11: 1 | P11: 16 | Q11: 19 | R11: 0 | S11: 0 | T11: 0 | U11: 0 | V11: 0 | W11: 0 | X11: 0 | Y11: 0 | Z11: 0 | AA11: 0 | AB11: 0 | AC11: 0 | AD11: 0 | AE11: 0 | AF11: 0 | AG11: 0 | AH11: 0 | AI11: 0 | AJ11: 0 | AK11: none | AP11: =IF(ISNUMBER(H11),IF(AND(H11=0,V11=0,AK11="none"),0.4,IF(AK11="exhaust",MAX(H11-V11,0.4),IF(AK11="ethereal",MAX(H11-V11,0.4),MAX(H11-V11,0.4)))),IF(AND(AK11="exhaust",OR(H11="X",H11="∞")),0.4,IF(OR(H11="X",H11="∞"),0.4,0.4))) -> 2 | AQ11: 0 | AR11: 0 | AT11: v0.110.1 sts2.info | AU11: 0 | AY11: =IFERROR(MAX(IF(IF(AND(F11="能力",AL11="能力持续"),(参数!$B$2-1)*参数!$B$3,0)+M11*O11*参数!$B$5*IF(AND(F11="能力",AL11="能力持续"),参数!$B$2,1)+P11*参数!$B$6*IF(AND(F11="能力",AL11="能力持续"),参数!$B$2,1)+R11*参数!$B$7*IF(AND(F11="能力",AL11="能力持续"),参数!$B$2,1)+V11*参数!$B$8+IF(X11<0,X11*参数!$B$13,X11*参数!$B$39)+IF(AE11<0,AE11*参数!$B$13,AE11*参数!$B$12)*参数!$B$2+AQ11*参数!$B$15+AB11*参数!$B$11+AF11*参数!$B$40*参数!$B$2+AG11*参数!$B$44*参数!$B$2+AH11*参数!$B$6*参数!$B$2+AI11*参数!$B$39*参数!$B$2+AJ11*参数!$B$6*参数!$B$2+Z11*参数!$B$13-T11*参数!$B$14-AD11*参数!$B$13+IF(ISNUMBER(AU11),AU11*参数!$B$38,0)-AV11*参数!$B$41-AW11*参数!$B$14>参数!$B$17,参数!$B$17+SQRT(IF(AND(F11="能力",AL11="能力持续"),(参数!$B$2-1)*参数!$B$3,0)+M11*O11*参数!$B$5*IF(AND(F11="能力",AL11="能力持续"),参数!$B$2,1)+P11*参数!$B$6*IF(AND(F11="能力",AL11="能力持续"),参数!$B$2,1)+R11*参数!$B$7*IF(AND(F11="能力",AL11="能力持续"),参数!$B$2,1)+V11*参数!$B$8+IF(X11<0,X11*参数!$B$13,X11*参数!$B$39)+IF(AE11<0,AE11*参数!$B$13,AE11*参数!$B$12)*参数!$B$2+AQ11*参数!$B$15+AB11*参数!$B$11+AF11*参数!$B$40*参数!$B$2+AG11*参数!$B$44*参数!$B$2+AH11*参数!$B$6*参数!$B$2+AI11*参数!$B$39*参数!$B$2+AJ11*参数!$B$6*参数!$B$2+Z11*参数!$B$13-T11*参数!$B$14-AD11*参数!$B$13+IF(ISNUMBER(AU11),AU11*参数!$B$38,0)-AV11*参数!$B$41-AW11*参数!$B$14-参数!$B$17)*参数!$B$18,IF(AND(F11="能力",AL11="能力持续"),(参数!$B$2-1)*参数!$B$3,0)+M11*O11*参数!$B$5*IF(AND(F11="能力",AL11="能力持续"),参数!$B$2,1)+P11*参数!$B$6*IF(AND(F11="能力",AL11="能力持续"),参数!$B$2,1)+R11*参数!$B$7*IF(AND(F11="能力",AL11="能力持续"),参数!$B$2,1)+V11*参数!$B$8+IF(X11<0,X11*参数!$B$13,X11*参数!$B$39)+IF(AE11<0,AE11*参数!$B$13,AE11*参数!$B$12)*参数!$B$2+AQ11*参数!$B$15+AB11*参数!$B$11+AF11*参数!$B$40*参数!$B$2+AG11*参数!$B$44*参数!$B$2+AH11*参数!$B$6*参数!$B$2+AI11*参数!$B$39*参数!$B$2+AJ11*参数!$B$6*参数!$B$2+Z11*参数!$B$13-T11*参数!$B$14-AD11*参数!$B$13+IF(ISNUMBER(AU11),AU11*参数!$B$38,0)-AV11*参数!$B$41-AW11*参数!$B$14),0),0) -> 14.135215 | AZ11: =AY11-MAX(AP11,0)*参数!$B$10 -> 8.1352146 | BA11: =IF(MAX(AP11,0)=0,AY11,AY11/MAX(AP11,0)) -> 7.0676073
A12: 11 | B12: ironclad_bloodletting | C12: 铁甲战士 | D12: 放血 | E12: Bloodletting | F12: 技能 | G12: 普通 | H12: 0 | I12: 0 | J12: 失去3点生命。 获得2点能量。 | L12: enemy_single | M12: 0 | N12: 0 | O12: 1 | P12: 0 | Q12: 0 | R12: 0 | S12: 0 | T12: 0 | U12: 0 | V12: 2 | W12: 2 | X12: 0 | Y12: 0 | Z12: 0 | AA12: 0 | AB12: 0 | AC12: 0 | AD12: 0 | AE12: 0 | AF12: 0 | AG12: 0 | AH12: 0 | AI12: 0 | AJ12: 0 | AK12: none | AP12: =IF(ISNUMBER(H12),IF(AND(H12=0,V12=0,AK12="none"),0.4,IF(AK12="exhaust",MAX(H12-V12,0.4),IF(AK12="ethereal",MAX(H12-V12,0.4),MAX(H12-V12,0.4)))),IF(AND(AK12="exhaust",OR(H12="X",H12="∞")),0.4,IF(OR(H12="X",H12="∞"),0.4,0.4))) -> 0.4 | AQ12: 0 | AR12: 0 | AT12: v0.110.1 sts2.info | AU12: 0 | AV12: 3 | AY12: =IFERROR(MAX(IF(IF(AND(F12="能力",AL12="能力持续"),(参数!$B$2-1)*参数!$B$3,0)+M12*O12*参数!$B$5*IF(AND(F12="能力",AL12="能力持续"),参数!$B$2,1)+P12*参数!$B$6*IF(AND(F12="能力",AL12="能力持续"),参数!$B$2,1)+R12*参数!$B$7*IF(AND(F12="能力",AL12="能力持续"),参数!$B$2,1)+V12*参数!$B$8+IF(X12<0,X12*参数!$B$13,X12*参数!$B$39)+IF(AE12<0,AE12*参数!$B$13,AE12*参数!$B$12)*参数!$B$2+AQ12*参数!$B$15+AB12*参数!$B$11+AF12*参数!$B$40*参数!$B$2+AG12*参数!$B$44*参数!$B$2+AH12*参数!$B$6*参数!$B$2+AI12*参数!$B$39*参数!$B$2+AJ12*参数!$B$6*参数!$B$2+Z12*参数!$B$13-T12*参数!$B$14-AD12*参数!$B$13+IF(ISNUMBER(AU12),AU12*参数!$B$38,0)-AV12*参数!$B$41-AW12*参数!$B$14>参数!$B$17,参数!$B$17+SQRT(IF(AND(F12="能力",AL12="能力持续"),(参数!$B$2-1)*参数!$B$3,0)+M12*O12*参数!$B$5*IF(AND(F12="能力",AL12="能力持续"),参数!$B$2,1)+P12*参数!$B$6*IF(AND(F12="能力",AL12="能力持续"),参数!$B$2,1)+R12*参数!$B$7*IF(AND(F12="能力",AL12="能力持续"),参数!$B$2,1)+V12*参数!$B$8+IF(X12<0,X12*参数!$B$13,X12*参数!$B$39)+IF(AE12<0,AE12*参数!$B$13,AE12*参数!$B$12)*参数!$B$2+AQ12*参数!$B$15+AB12*参数!$B$11+AF12*参数!$B$40*参数!$B$2+AG12*参数!$B$44*参数!$B$2+AH12*参数!$B$6*参数!$B$2+AI12*参数!$B$39*参数!$B$2+AJ12*参数!$B$6*参数!$B$2+Z12*参数!$B$13-T12*参数!$B$14-AD12*参数!$B$13+IF(ISNUMBER(AU12),AU12*参数!$B$38,0)-AV12*参数!$B$41-AW12*参数!$B$14-参数!$B$17)*参数!$B$18,IF(AND(F12="能力",AL12="能力持续"),(参数!$B$2-1)*参数!$B$3,0)+M12*O12*参数!$B$5*IF(AND(F12="能力",AL12="能力持续"),参数!$B$2,1)+P12*参数!$B$6*IF(AND(F12="能力",AL12="能力持续"),参数!$B$2,1)+R12*参数!$B$7*IF(AND(F12="能力",AL12="能力持续"),参数!$B$2,1)+V12*参数!$B$8+IF(X12<0,X12*参数!$B$13,X12*参数!$B$39)+IF(AE12<0,AE12*参数!$B$13,AE12*参数!$B$12)*参数!$B$2+AQ12*参数!$B$15+AB12*参数!$B$11+AF12*参数!$B$40*参数!$B$2+AG12*参数!$B$44*参数!$B$2+AH12*参数!$B$6*参数!$B$2+AI12*参数!$B$39*参数!$B$2+AJ12*参数!$B$6*参数!$B$2+Z12*参数!$B$13-T12*参数!$B$14-AD12*参数!$B$13+IF(ISNUMBER(AU12),AU12*参数!$B$38,0)-AV12*参数!$B$41-AW12*参数!$B$14),0),0) -> 0 | AZ12: =AY12-MAX(AP12,0)*参数!$B$10 -> -1.2 | BA12: =IF(MAX(AP12,0)=0,AY12,AY12/MAX(AP12,0)) -> 0
A13: 12 | B13: ironclad_bludgeon | C13: 铁甲战士 | D13: 重锤 | E13: Bludgeon | F13: 攻击 | G13: 罕见 | H13: 3 | I13: 3 | J13: 造成32点伤害。 | L13: enemy_single | M13: 32 | N13: 42 | O13: 1 | P13: 0 | Q13: 0 | R13: 0 | S13: 0 | T13: 0 | U13: 0 | V13: 0 | W13: 0 | X13: 0 | Y13: 0 | Z13: 0 | AA13: 0 | AB13: 0 | AC13: 0 | AD13: 0 | AE13: 0 | AF13: 0 | AG13: 0 | AH13: 0 | AI13: 0 | AJ13: 0 | AK13: none | AP13: =IF(ISNUMBER(H13),IF(AND(H13=0,V13=0,AK13="none"),0.4,IF(AK13="exhaust",MAX(H13-V13,0.4),IF(AK13="ethereal",MAX(H13-V13,0.4),MAX(H13-V13,0.4)))),IF(AND(AK13="exhaust",OR(H13="X",H13="∞")),0.4,IF(OR(H13="X",H13="∞"),0.4,0.4))) -> 3 | AQ13: 0 | AR13: 0 | AT13: v0.110.1 sts2.info | AU13: 0 | AY13: =IFERROR(MAX(IF(IF(AND(F13="能力",AL13="能力持续"),(参数!$B$2-1)*参数!$B$3,0)+M13*O13*参数!$B$5*IF(AND(F13="能力",AL13="能力持续"),参数!$B$2,1)+P13*参数!$B$6*IF(AND(F13="能力",AL13="能力持续"),参数!$B$2,1)+R13*参数!$B$7*IF(AND(F13="能力",AL13="能力持续"),参数!$B$2,1)+V13*参数!$B$8+IF(X13<0,X13*参数!$B$13,X13*参数!$B$39)+IF(AE13<0,AE13*参数!$B$13,AE13*参数!$B$12)*参数!$B$2+AQ13*参数!$B$15+AB13*参数!$B$11+AF13*参数!$B$40*参数!$B$2+AG13*参数!$B$44*参数!$B$2+AH13*参数!$B$6*参数!$B$2+AI13*参数!$B$39*参数!$B$2+AJ13*参数!$B$6*参数!$B$2+Z13*参数!$B$13-T13*参数!$B$14-AD13*参数!$B$13+IF(ISNUMBER(AU13),AU13*参数!$B$38,0)-AV13*参数!$B$41-AW13*参数!$B$14>参数!$B$17,参数!$B$17+SQRT(IF(AND(F13="能力",AL13="能力持续"),(参数!$B$2-1)*参数!$B$3,0)+M13*O13*参数!$B$5*IF(AND(F13="能力",AL13="能力持续"),参数!$B$2,1)+P13*参数!$B$6*IF(AND(F13="能力",AL13="能力持续"),参数!$B$2,1)+R13*参数!$B$7*IF(AND(F13="能力",AL13="能力持续"),参数!$B$2,1)+V13*参数!$B$8+IF(X13<0,X13*参数!$B$13,X13*参数!$B$39)+IF(AE13<0,AE13*参数!$B$13,AE13*参数!$B$12)*参数!$B$2+AQ13*参数!$B$15+AB13*参数!$B$11+AF13*参数!$B$40*参数!$B$2+AG13*参数!$B$44*参数!$B$2+AH13*参数!$B$6*参数!$B$2+AI13*参数!$B$39*参数!$B$2+AJ13*参数!$B$6*参数!$B$2+Z13*参数!$B$13-T13*参数!$B$14-AD13*参数!$B$13+IF(ISNUMBER(AU13),AU13*参数!$B$38,0)-AV13*参数!$B$41-AW13*参数!$B$14-参数!$B$17)*参数!$B$18,IF(AND(F13="能力",AL13="能力持续"),(参数!$B$2-1)*参数!$B$3,0)+M13*O13*参数!$B$5*IF(AND(F13="能力",AL13="能力持续"),参数!$B$2,1)+P13*参数!$B$6*IF(AND(F13="能力",AL13="能力持续"),参数!$B$2,1)+R13*参数!$B$7*IF(AND(F13="能力",AL13="能力持续"),参数!$B$2,1)+V13*参数!$B$8+IF(X13<0,X13*参数!$B$13,X13*参数!$B$39)+IF(AE13<0,AE13*参数!$B$13,AE13*参数!$B$12)*参数!$B$2+AQ13*参数!$B$15+AB13*参数!$B$11+AF13*参数!$B$40*参数!$B$2+AG13*参数!$B$44*参数!$B$2+AH13*参数!$B$6*参数!$B$2+AI13*参数!$B$39*参数!$B$2+AJ13*参数!$B$6*参数!$B$2+Z13*参数!$B$13-T13*参数!$B$14-AD13*参数!$B$13+IF(ISNUMBER(AU13),AU13*参数!$B$38,0)-AV13*参数!$B$41-AW13*参数!$B$14),0),0) -> 17.035624 | AZ13: =AY13-MAX(AP13,0)*参数!$B$10 -> 8.0356236 | BA13: =IF(MAX(AP13,0)=0,AY13,AY13/MAX(AP13,0)) -> 5.6785412
A14: 13 | B14: ironclad_body_slam | C14: 铁甲战士 | D14: 全身撞击 | E14: Body Slam | F14: 攻击 | G14: 普通 | H14: 1 | I14: 1 | J14: 造成你当前格挡值的伤害。 | L14: enemy_single | M14: 10 | N14: 0 | O14: 1 | P14: 0 | Q14: 0 | R14: 0 | S14: 0 | T14: 0 | U14: 0 | V14: 0 | W14: 0 | X14: 0 | Y14: 0 | Z14: 0 | AA14: 0 | AB14: 0 | AC14: 0 | AD14: 0 | AE14: 0 | AF14: 0 | AG14: 0 | AH14: 0 | AI14: 0 | AJ14: 0 | AK14: none | AP14: =IF(ISNUMBER(H14),IF(AND(H14=0,V14=0,AK14="none"),0.4,IF(AK14="exhaust",MAX(H14-V14,0.4),IF(AK14="ethereal",MAX(H14-V14,0.4),MAX(H14-V14,0.4)))),IF(AND(AK14="exhaust",OR(H14="X",H14="∞")),0.4,IF(OR(H14="X",H14="∞"),0.4,0.4))) -> 1 | AQ14: 0 | AR14: 0 | AT14: v0.110.1 sts2.info | AU14: 0 | AY14: =IFERROR(MAX(IF(IF(AND(F14="能力",AL14="能力持续"),(参数!$B$2-1)*参数!$B$3,0)+M14*O14*参数!$B$5*IF(AND(F14="能力",AL14="能力持续"),参数!$B$2,1)+P14*参数!$B$6*IF(AND(F14="能力",AL14="能力持续"),参数!$B$2,1)+R14*参数!$B$7*IF(AND(F14="能力",AL14="能力持续"),参数!$B$2,1)+V14*参数!$B$8+IF(X14<0,X14*参数!$B$13,X14*参数!$B$39)+IF(AE14<0,AE14*参数!$B$13,AE14*参数!$B$12)*参数!$B$2+AQ14*参数!$B$15+AB14*参数!$B$11+AF14*参数!$B$40*参数!$B$2+AG14*参数!$B$44*参数!$B$2+AH14*参数!$B$6*参数!$B$2+AI14*参数!$B$39*参数!$B$2+AJ14*参数!$B$6*参数!$B$2+Z14*参数!$B$13-T14*参数!$B$14-AD14*参数!$B$13+IF(ISNUMBER(AU14),AU14*参数!$B$38,0)-AV14*参数!$B$41-AW14*参数!$B$14>参数!$B$17,参数!$B$17+SQRT(IF(AND(F14="能力",AL14="能力持续"),(参数!$B$2-1)*参数!$B$3,0)+M14*O14*参数!$B$5*IF(AND(F14="能力",AL14="能力持续"),参数!$B$2,1)+P14*参数!$B$6*IF(AND(F14="能力",AL14="能力持续"),参数!$B$2,1)+R14*参数!$B$7*IF(AND(F14="能力",AL14="能力持续"),参数!$B$2,1)+V14*参数!$B$8+IF(X14<0,X14*参数!$B$13,X14*参数!$B$39)+IF(AE14<0,AE14*参数!$B$13,AE14*参数!$B$12)*参数!$B$2+AQ14*参数!$B$15+AB14*参数!$B$11+AF14*参数!$B$40*参数!$B$2+AG14*参数!$B$44*参数!$B$2+AH14*参数!$B$6*参数!$B$2+AI14*参数!$B$39*参数!$B$2+AJ14*参数!$B$6*参数!$B$2+Z14*参数!$B$13-T14*参数!$B$14-AD14*参数!$B$13+IF(ISNUMBER(AU14),AU14*参数!$B$38,0)-AV14*参数!$B$41-AW14*参数!$B$14-参数!$B$17)*参数!$B$18,IF(AND(F14="能力",AL14="能力持续"),(参数!$B$2-1)*参数!$B$3,0)+M14*O14*参数!$B$5*IF(AND(F14="能力",AL14="能力持续"),参数!$B$2,1)+P14*参数!$B$6*IF(AND(F14="能力",AL14="能力持续"),参数!$B$2,1)+R14*参数!$B$7*IF(AND(F14="能力",AL14="能力持续"),参数!$B$2,1)+V14*参数!$B$8+IF(X14<0,X14*参数!$B$13,X14*参数!$B$39)+IF(AE14<0,AE14*参数!$B$13,AE14*参数!$B$12)*参数!$B$2+AQ14*参数!$B$15+AB14*参数!$B$11+AF14*参数!$B$40*参数!$B$2+AG14*参数!$B$44*参数!$B$2+AH14*参数!$B$6*参数!$B$2+AI14*参数!$B$39*参数!$B$2+AJ14*参数!$B$6*参数!$B$2+Z14*参数!$B$13-T14*参数!$B$14-AD14*参数!$B$13+IF(ISNUMBER(AU14),AU14*参数!$B$38,0)-AV14*参数!$B$41-AW14*参数!$B$14),0),0) -> 10 | AZ14: =AY14-MAX(AP14,0)*参数!$B$10 -> 7 | BA14: =IF(MAX(AP14,0)=0,AY14,AY14/MAX(AP14,0)) -> 10
A15: 14 | B15: ironclad_brand | C15: 铁甲战士 | D15: 烙印 | E15: Brand | F15: 技能 | G15: 稀有 | H15: 0 | I15: 0 | J15: 失去1点生命。 消耗1张牌。 获得1点力量。 | K15: 含消耗其他牌效果 | L15: enemy_single | M15: 0 | N15: 0 | O15: 1 | P15: 0 | Q15: 0 | R15: 0 | S15: 0 | T15: 0 | U15: 0 | V15: 0 | W15: 0 | X15: 0 | Y15: 0 | Z15: 0 | AA15: 0 | AB15: 0 | AC15: 0 | AD15: 1 | AE15: 1 | AF15: 0 | AG15: 0 | AH15: 0 | AI15: 0 | AJ15: 0 | AK15: none | AO15: 含消耗其他牌效果 | AP15: =IF(ISNUMBER(H15),IF(AND(H15=0,V15=0,AK15="none"),0.4,IF(AK15="exhaust",MAX(H15-V15,0.4),IF(AK15="ethereal",MAX(H15-V15,0.4),MAX(H15-V15,0.4)))),IF(AND(AK15="exhaust",OR(H15="X",H15="∞")),0.4,IF(OR(H15="X",H15="∞"),0.4,0.4))) -> 0.4 | AQ15: 0 | AR15: 0 | AT15: v0.110.1 sts2.info | AU15: 0 | AY15: =IFERROR(MAX(IF(IF(AND(F15="能力",AL15="能力持续"),(参数!$B$2-1)*参数!$B$3,0)+M15*O15*参数!$B$5*IF(AND(F15="能力",AL15="能力持续"),参数!$B$2,1)+P15*参数!$B$6*IF(AND(F15="能力",AL15="能力持续"),参数!$B$2,1)+R15*参数!$B$7*IF(AND(F15="能力",AL15="能力持续"),参数!$B$2,1)+V15*参数!$B$8+IF(X15<0,X15*参数!$B$13,X15*参数!$B$39)+IF(AE15<0,AE15*参数!$B$13,AE15*参数!$B$12)*参数!$B$2+AQ15*参数!$B$15+AB15*参数!$B$11+AF15*参数!$B$40*参数!$B$2+AG15*参数!$B$44*参数!$B$2+AH15*参数!$B$6*参数!$B$2+AI15*参数!$B$39*参数!$B$2+AJ15*参数!$B$6*参数!$B$2+Z15*参数!$B$13-T15*参数!$B$14-AD15*参数!$B$13+IF(ISNUMBER(AU15),AU15*参数!$B$38,0)-AV15*参数!$B$41-AW15*参数!$B$14>参数!$B$17,参数!$B$17+SQRT(IF(AND(F15="能力",AL15="能力持续"),(参数!$B$2-1)*参数!$B$3,0)+M15*O15*参数!$B$5*IF(AND(F15="能力",AL15="能力持续"),参数!$B$2,1)+P15*参数!$B$6*IF(AND(F15="能力",AL15="能力持续"),参数!$B$2,1)+R15*参数!$B$7*IF(AND(F15="能力",AL15="能力持续"),参数!$B$2,1)+V15*参数!$B$8+IF(X15<0,X15*参数!$B$13,X15*参数!$B$39)+IF(AE15<0,AE15*参数!$B$13,AE15*参数!$B$12)*参数!$B$2+AQ15*参数!$B$15+AB15*参数!$B$11+AF15*参数!$B$40*参数!$B$2+AG15*参数!$B$44*参数!$B$2+AH15*参数!$B$6*参数!$B$2+AI15*参数!$B$39*参数!$B$2+AJ15*参数!$B$6*参数!$B$2+Z15*参数!$B$13-T15*参数!$B$14-AD15*参数!$B$13+IF(ISNUMBER(AU15),AU15*参数!$B$38,0)-AV15*参数!$B$41-AW15*参数!$B$14-参数!$B$17)*参数!$B$18,IF(AND(F15="能力",AL15="能力持续"),(参数!$B$2-1)*参数!$B$3,0)+M15*O15*参数!$B$5*IF(AND(F15="能力",AL15="能力持续"),参数!$B$2,1)+P15*参数!$B$6*IF(AND(F15="能力",AL15="能力持续"),参数!$B$2,1)+R15*参数!$B$7*IF(AND(F15="能力",AL15="能力持续"),参数!$B$2,1)+V15*参数!$B$8+IF(X15<0,X15*参数!$B$13,X15*参数!$B$39)+IF(AE15<0,AE15*参数!$B$13,AE15*参数!$B$12)*参数!$B$2+AQ15*参数!$B$15+AB15*参数!$B$11+AF15*参数!$B$40*参数!$B$2+AG15*参数!$B$44*参数!$B$2+AH15*参数!$B$6*参数!$B$2+AI15*参数!$B$39*参数!$B$2+AJ15*参数!$B$6*参数!$B$2+Z15*参数!$B$13-T15*参数!$B$14-AD15*参数!$B$13+IF(ISNUMBER(AU15),AU15*参数!$B$38,0)-AV15*参数!$B$41-AW15*参数!$B$14),0),0) -> 3.3 | AZ15: =AY15-MAX(AP15,0)*参数!$B$10 -> 2.1 | BA15: =IF(MAX(AP15,0)=0,AY15,AY15/MAX(AP15,0)) -> 8.25
A16: 15 | B16: ironclad_break | C16: 铁甲战士 | D16: 破击 | E16: Break | F16: 攻击 | G16: 远古 | H16: 2 | I16: 2 | J16: 造成20点伤害。 给予5层易伤。 | L16: enemy_single | M16: 20 | N16: 24 | O16: 1 | P16: 0 | Q16: 0 | R16: 0 | S16: 0 | T16: 0 | U16: 0 | V16: 0 | W16: 0 | X16: 0 | Y16: 0 | Z16: 0 | AA16: 5 | AB16: 5 | AC16: 6 | AD16: 0 | AE16: 0 | AF16: 0 | AG16: 0 | AH16: 0 | AI16: 0 | AJ16: 0 | AK16: none | AP16: =IF(ISNUMBER(H16),IF(AND(H16=0,V16=0,AK16="none"),0.4,IF(AK16="exhaust",MAX(H16-V16,0.4),IF(AK16="ethereal",MAX(H16-V16,0.4),MAX(H16-V16,0.4)))),IF(AND(AK16="exhaust",OR(H16="X",H16="∞")),0.4,IF(OR(H16="X",H16="∞"),0.4,0.4))) -> 2 | AQ16: 0 | AR16: 0 | AT16: v0.110.1 sts2.info | AU16: 0 | AY16: =IFERROR(MAX(IF(IF(AND(F16="能力",AL16="能力持续"),(参数!$B$2-1)*参数!$B$3,0)+M16*O16*参数!$B$5*IF(AND(F16="能力",AL16="能力持续"),参数!$B$2,1)+P16*参数!$B$6*IF(AND(F16="能力",AL16="能力持续"),参数!$B$2,1)+R16*参数!$B$7*IF(AND(F16="能力",AL16="能力持续"),参数!$B$2,1)+V16*参数!$B$8+IF(X16<0,X16*参数!$B$13,X16*参数!$B$39)+IF(AE16<0,AE16*参数!$B$13,AE16*参数!$B$12)*参数!$B$2+AQ16*参数!$B$15+AB16*参数!$B$11+AF16*参数!$B$40*参数!$B$2+AG16*参数!$B$44*参数!$B$2+AH16*参数!$B$6*参数!$B$2+AI16*参数!$B$39*参数!$B$2+AJ16*参数!$B$6*参数!$B$2+Z16*参数!$B$13-T16*参数!$B$14-AD16*参数!$B$13+IF(ISNUMBER(AU16),AU16*参数!$B$38,0)-AV16*参数!$B$41-AW16*参数!$B$14>参数!$B$17,参数!$B$17+SQRT(IF(AND(F16="能力",AL16="能力持续"),(参数!$B$2-1)*参数!$B$3,0)+M16*O16*参数!$B$5*IF(AND(F16="能力",AL16="能力持续"),参数!$B$2,1)+P16*参数!$B$6*IF(AND(F16="能力",AL16="能力持续"),参数!$B$2,1)+R16*参数!$B$7*IF(AND(F16="能力",AL16="能力持续"),参数!$B$2,1)+V16*参数!$B$8+IF(X16<0,X16*参数!$B$13,X16*参数!$B$39)+IF(AE16<0,AE16*参数!$B$13,AE16*参数!$B$12)*参数!$B$2+AQ16*参数!$B$15+AB16*参数!$B$11+AF16*参数!$B$40*参数!$B$2+AG16*参数!$B$44*参数!$B$2+AH16*参数!$B$6*参数!$B$2+AI16*参数!$B$39*参数!$B$2+AJ16*参数!$B$6*参数!$B$2+Z16*参数!$B$13-T16*参数!$B$14-AD16*参数!$B$13+IF(ISNUMBER(AU16),AU16*参数!$B$38,0)-AV16*参数!$B$41-AW16*参数!$B$14-参数!$B$17)*参数!$B$18,IF(AND(F16="能力",AL16="能力持续"),(参数!$B$2-1)*参数!$B$3,0)+M16*O16*参数!$B$5*IF(AND(F16="能力",AL16="能力持续"),参数!$B$2,1)+P16*参数!$B$6*IF(AND(F16="能力",AL16="能力持续"),参数!$B$2,1)+R16*参数!$B$7*IF(AND(F16="能力",AL16="能力持续"),参数!$B$2,1)+V16*参数!$B$8+IF(X16<0,X16*参数!$B$13,X16*参数!$B$39)+IF(AE16<0,AE16*参数!$B$13,AE16*参数!$B$12)*参数!$B$2+AQ16*参数!$B$15+AB16*参数!$B$11+AF16*参数!$B$40*参数!$B$2+AG16*参数!$B$44*参数!$B$2+AH16*参数!$B$6*参数!$B$2+AI16*参数!$B$39*参数!$B$2+AJ16*参数!$B$6*参数!$B$2+Z16*参数!$B$13-T16*参数!$B$14-AD16*参数!$B$13+IF(ISNUMBER(AU16),AU16*参数!$B$38,0)-AV16*参数!$B$41-AW16*参数!$B$14),0),0) -> 16.093029 | AZ16: =AY16-MAX(AP16,0)*参数!$B$10 -> 10.093029 | BA16: =IF(MAX(AP16,0)=0,AY16,AY16/MAX(AP16,0)) -> 8.0465144
A17: 16 | B17: ironclad_breakthrough | C17: 铁甲战士 | D17: 突破 | E17: Breakthrough | F17: 攻击 | G17: 普通 | H17: 1 | I17: 1 | J17: 失去1点生命。 对所有敌人造成9点伤害。 | L17: enemy_all | M17: 9 | N17: 13 | O17: 1 | P17: 0 | Q17: 0 | R17: 0 | S17: 0 | T17: 0 | U17: 0 | V17: 0 | W17: 0 | X17: 0 | Y17: 0 | Z17: 0 | AA17: 0 | AB17: 0 | AC17: 0 | AD17: 0 | AE17: 0 | AF17: 0 | AG17: 0 | AH17: 0 | AI17: 0 | AJ17: 0 | AK17: none | AN17: 群体攻击 | AP17: =IF(ISNUMBER(H17),IF(AND(H17=0,V17=0,AK17="none"),0.4,IF(AK17="exhaust",MAX(H17-V17,0.4),IF(AK17="ethereal",MAX(H17-V17,0.4),MAX(H17-V17,0.4)))),IF(AND(AK17="exhaust",OR(H17="X",H17="∞")),0.4,IF(OR(H17="X",H17="∞"),0.4,0.4))) -> 1 | AQ17: 0 | AR17: 0 | AT17: v0.110.1 sts2.info | AU17: 0 | AY17: =IFERROR(MAX(IF(IF(AND(F17="能力",AL17="能力持续"),(参数!$B$2-1)*参数!$B$3,0)+M17*O17*参数!$B$5*IF(AND(F17="能力",AL17="能力持续"),参数!$B$2,1)+P17*参数!$B$6*IF(AND(F17="能力",AL17="能力持续"),参数!$B$2,1)+R17*参数!$B$7*IF(AND(F17="能力",AL17="能力持续"),参数!$B$2,1)+V17*参数!$B$8+IF(X17<0,X17*参数!$B$13,X17*参数!$B$39)+IF(AE17<0,AE17*参数!$B$13,AE17*参数!$B$12)*参数!$B$2+AQ17*参数!$B$15+AB17*参数!$B$11+AF17*参数!$B$40*参数!$B$2+AG17*参数!$B$44*参数!$B$2+AH17*参数!$B$6*参数!$B$2+AI17*参数!$B$39*参数!$B$2+AJ17*参数!$B$6*参数!$B$2+Z17*参数!$B$13-T17*参数!$B$14-AD17*参数!$B$13+IF(ISNUMBER(AU17),AU17*参数!$B$38,0)-AV17*参数!$B$41-AW17*参数!$B$14>参数!$B$17,参数!$B$17+SQRT(IF(AND(F17="能力",AL17="能力持续"),(参数!$B$2-1)*参数!$B$3,0)+M17*O17*参数!$B$5*IF(AND(F17="能力",AL17="能力持续"),参数!$B$2,1)+P17*参数!$B$6*IF(AND(F17="能力",AL17="能力持续"),参数!$B$2,1)+R17*参数!$B$7*IF(AND(F17="能力",AL17="能力持续"),参数!$B$2,1)+V17*参数!$B$8+IF(X17<0,X17*参数!$B$13,X17*参数!$B$39)+IF(AE17<0,AE17*参数!$B$13,AE17*参数!$B$12)*参数!$B$2+AQ17*参数!$B$15+AB17*参数!$B$11+AF17*参数!$B$40*参数!$B$2+AG17*参数!$B$44*参数!$B$2+AH17*参数!$B$6*参数!$B$2+AI17*参数!$B$39*参数!$B$2+AJ17*参数!$B$6*参数!$B$2+Z17*参数!$B$13-T17*参数!$B$14-AD17*参数!$B$13+IF(ISNUMBER(AU17),AU17*参数!$B$38,0)-AV17*参数!$B$41-AW17*参数!$B$14-参数!$B$17)*参数!$B$18,IF(AND(F17="能力",AL17="能力持续"),(参数!$B$2-1)*参数!$B$3,0)+M17*O17*参数!$B$5*IF(AND(F17="能力",AL17="能力持续"),参数!$B$2,1)+P17*参数!$B$6*IF(AND(F17="能力",AL17="能力持续"),参数!$B$2,1)+R17*参数!$B$7*IF(AND(F17="能力",AL17="能力持续"),参数!$B$2,1)+V17*参数!$B$8+IF(X17<0,X17*参数!$B$13,X17*参数!$B$39)+IF(AE17<0,AE17*参数!$B$13,AE17*参数!$B$12)*参数!$B$2+AQ17*参数!$B$15+AB17*参数!$B$11+AF17*参数!$B$40*参数!$B$2+AG17*参数!$B$44*参数!$B$2+AH17*参数!$B$6*参数!$B$2+AI17*参数!$B$39*参数!$B$2+AJ17*参数!$B$6*参数!$B$2+Z17*参数!$B$13-T17*参数!$B$14-AD17*参数!$B$13+IF(ISNUMBER(AU17),AU17*参数!$B$38,0)-AV17*参数!$B$41-AW17*参数!$B$14),0),0) -> 9 | AZ17: =AY17-MAX(AP17,0)*参数!$B$10 -> 6 | BA17: =IF(MAX(AP17,0)=0,AY17,AY17/MAX(AP17,0)) -> 9
A18: 17 | B18: ironclad_bully | C18: 铁甲战士 | D18: 欺凌 | E18: Bully | F18: 攻击 | G18: 罕见 | H18: 0 | I18: 0 | J18: 造成4点伤害。 该敌人身上每有一层易伤就额外造成2点伤害。 | L18: enemy_single | M18: 6 | N18: 8 | O18: 1 | P18: 0 | Q18: 0 | R18: 0 | S18: 0 | T18: 0 | U18: 0 | V18: 0 | W18: 0 | X18: 0 | Y18: 0 | Z18: 0 | AA18: 0 | AB18: 0 | AC18: 0 | AD18: 0 | AE18: 0 | AF18: 0 | AG18: 0 | AH18: 0 | AI18: 0 | AJ18: 0 | AK18: none | AP18: =IF(ISNUMBER(H18),IF(AND(H18=0,V18=0,AK18="none"),0.4,IF(AK18="exhaust",MAX(H18-V18,0.4),IF(AK18="ethereal",MAX(H18-V18,0.4),MAX(H18-V18,0.4)))),IF(AND(AK18="exhaust",OR(H18="X",H18="∞")),0.4,IF(OR(H18="X",H18="∞"),0.4,0.4))) -> 0.4 | AQ18: 0 | AR18: 0 | AT18: v0.110.1 sts2.info | AU18: 0 | AY18: =IFERROR(MAX(IF(IF(AND(F18="能力",AL18="能力持续"),(参数!$B$2-1)*参数!$B$3,0)+M18*O18*参数!$B$5*IF(AND(F18="能力",AL18="能力持续"),参数!$B$2,1)+P18*参数!$B$6*IF(AND(F18="能力",AL18="能力持续"),参数!$B$2,1)+R18*参数!$B$7*IF(AND(F18="能力",AL18="能力持续"),参数!$B$2,1)+V18*参数!$B$8+IF(X18<0,X18*参数!$B$13,X18*参数!$B$39)+IF(AE18<0,AE18*参数!$B$13,AE18*参数!$B$12)*参数!$B$2+AQ18*参数!$B$15+AB18*参数!$B$11+AF18*参数!$B$40*参数!$B$2+AG18*参数!$B$44*参数!$B$2+AH18*参数!$B$6*参数!$B$2+AI18*参数!$B$39*参数!$B$2+AJ18*参数!$B$6*参数!$B$2+Z18*参数!$B$13-T18*参数!$B$14-AD18*参数!$B$13+IF(ISNUMBER(AU18),AU18*参数!$B$38,0)-AV18*参数!$B$41-AW18*参数!$B$14>参数!$B$17,参数!$B$17+SQRT(IF(AND(F18="能力",AL18="能力持续"),(参数!$B$2-1)*参数!$B$3,0)+M18*O18*参数!$B$5*IF(AND(F18="能力",AL18="能力持续"),参数!$B$2,1)+P18*参数!$B$6*IF(AND(F18="能力",AL18="能力持续"),参数!$B$2,1)+R18*参数!$B$7*IF(AND(F18="能力",AL18="能力持续"),参数!$B$2,1)+V18*参数!$B$8+IF(X18<0,X18*参数!$B$13,X18*参数!$B$39)+IF(AE18<0,AE18*参数!$B$13,AE18*参数!$B$12)*参数!$B$2+AQ18*参数!$B$15+AB18*参数!$B$11+AF18*参数!$B$40*参数!$B$2+AG18*参数!$B$44*参数!$B$2+AH18*参数!$B$6*参数!$B$2+AI18*参数!$B$39*参数!$B$2+AJ18*参数!$B$6*参数!$B$2+Z18*参数!$B$13-T18*参数!$B$14-AD18*参数!$B$13+IF(ISNUMBER(AU18),AU18*参数!$B$38,0)-AV18*参数!$B$41-AW18*参数!$B$14-参数!$B$17)*参数!$B$18,IF(AND(F18="能力",AL18="能力持续"),(参数!$B$2-1)*参数!$B$3,0)+M18*O18*参数!$B$5*IF(AND(F18="能力",AL18="能力持续"),参数!$B$2,1)+P18*参数!$B$6*IF(AND(F18="能力",AL18="能力持续"),参数!$B$2,1)+R18*参数!$B$7*IF(AND(F18="能力",AL18="能力持续"),参数!$B$2,1)+V18*参数!$B$8+IF(X18<0,X18*参数!$B$13,X18*参数!$B$39)+IF(AE18<0,AE18*参数!$B$13,AE18*参数!$B$12)*参数!$B$2+AQ18*参数!$B$15+AB18*参数!$B$11+AF18*参数!$B$40*参数!$B$2+AG18*参数!$B$44*参数!$B$2+AH18*参数!$B$6*参数!$B$2+AI18*参数!$B$39*参数!$B$2+AJ18*参数!$B$6*参数!$B$2+Z18*参数!$B$13-T18*参数!$B$14-AD18*参数!$B$13+IF(ISNUMBER(AU18),AU18*参数!$B$38,0)-AV18*参数!$B$41-AW18*参数!$B$14),0),0) -> 6 | AZ18: =AY18-MAX(AP18,0)*参数!$B$10 -> 4.8 | BA18: =IF(MAX(AP18,0)=0,AY18,AY18/MAX(AP18,0)) -> 15
A19: 18 | B19: ironclad_burning_pact | C19: 铁甲战士 | D19: 燃烧契约 | E19: Burning Pact | F19: 技能 | G19: 罕见 | H19: 1 | I19: 1 | J19: 消耗1张牌。 抽2张牌。 | K19: 含消耗其他牌效果 | L19: enemy_single | M19: 0 | N19: 0 | O19: 1 | P19: 0 | Q19: 0 | R19: 2 | S19: 3 | T19: 0 | U19: 0 | V19: 0 | W19: 0 | X19: 0 | Y19: 0 | Z19: 0 | AA19: 0 | AB19: 0 | AC19: 0 | AD19: 1 | AE19: 0 | AF19: 0 | AG19: 0 | AH19: 0 | AI19: 0 | AJ19: 0 | AK19: none | AO19: 含消耗其他牌效果 | AP19: =IF(ISNUMBER(H19),IF(AND(H19=0,V19=0,AK19="none"),0.4,IF(AK19="exhaust",MAX(H19-V19,0.4),IF(AK19="ethereal",MAX(H19-V19,0.4),MAX(H19-V19,0.4)))),IF(AND(AK19="exhaust",OR(H19="X",H19="∞")),0.4,IF(OR(H19="X",H19="∞"),0.4,0.4))) -> 1 | AQ19: 0 | AR19: 0 | AT19: v0.110.1 sts2.info | AU19: 0 | AW19: 1 | AY19: =IFERROR(MAX(IF(IF(AND(F19="能力",AL19="能力持续"),(参数!$B$2-1)*参数!$B$3,0)+M19*O19*参数!$B$5*IF(AND(F19="能力",AL19="能力持续"),参数!$B$2,1)+P19*参数!$B$6*IF(AND(F19="能力",AL19="能力持续"),参数!$B$2,1)+R19*参数!$B$7*IF(AND(F19="能力",AL19="能力持续"),参数!$B$2,1)+V19*参数!$B$8+IF(X19<0,X19*参数!$B$13,X19*参数!$B$39)+IF(AE19<0,AE19*参数!$B$13,AE19*参数!$B$12)*参数!$B$2+AQ19*参数!$B$15+AB19*参数!$B$11+AF19*参数!$B$40*参数!$B$2+AG19*参数!$B$44*参数!$B$2+AH19*参数!$B$6*参数!$B$2+AI19*参数!$B$39*参数!$B$2+AJ19*参数!$B$6*参数!$B$2+Z19*参数!$B$13-T19*参数!$B$14-AD19*参数!$B$13+IF(ISNUMBER(AU19),AU19*参数!$B$38,0)-AV19*参数!$B$41-AW19*参数!$B$14>参数!$B$17,参数!$B$17+SQRT(IF(AND(F19="能力",AL19="能力持续"),(参数!$B$2-1)*参数!$B$3,0)+M19*O19*参数!$B$5*IF(AND(F19="能力",AL19="能力持续"),参数!$B$2,1)+P19*参数!$B$6*IF(AND(F19="能力",AL19="能力持续"),参数!$B$2,1)+R19*参数!$B$7*IF(AND(F19="能力",AL19="能力持续"),参数!$B$2,1)+V19*参数!$B$8+IF(X19<0,X19*参数!$B$13,X19*参数!$B$39)+IF(AE19<0,AE19*参数!$B$13,AE19*参数!$B$12)*参数!$B$2+AQ19*参数!$B$15+AB19*参数!$B$11+AF19*参数!$B$40*参数!$B$2+AG19*参数!$B$44*参数!$B$2+AH19*参数!$B$6*参数!$B$2+AI19*参数!$B$39*参数!$B$2+AJ19*参数!$B$6*参数!$B$2+Z19*参数!$B$13-T19*参数!$B$14-AD19*参数!$B$13+IF(ISNUMBER(AU19),AU19*参数!$B$38,0)-AV19*参数!$B$41-AW19*参数!$B$14-参数!$B$17)*参数!$B$18,IF(AND(F19="能力",AL19="能力持续"),(参数!$B$2-1)*参数!$B$3,0)+M19*O19*参数!$B$5*IF(AND(F19="能力",AL19="能力持续"),参数!$B$2,1)+P19*参数!$B$6*IF(AND(F19="能力",AL19="能力持续"),参数!$B$2,1)+R19*参数!$B$7*IF(AND(F19="能力",AL19="能力持续"),参数!$B$2,1)+V19*参数!$B$8+IF(X19<0,X19*参数!$B$13,X19*参数!$B$39)+IF(AE19<0,AE19*参数!$B$13,AE19*参数!$B$12)*参数!$B$2+AQ19*参数!$B$15+AB19*参数!$B$11+AF19*参数!$B$40*参数!$B$2+AG19*参数!$B$44*参数!$B$2+AH19*参数!$B$6*参数!$B$2+AI19*参数!$B$39*参数!$B$2+AJ19*参数!$B$6*参数!$B$2+Z19*参数!$B$13-T19*参数!$B$14-AD19*参数!$B$13+IF(ISNUMBER(AU19),AU19*参数!$B$38,0)-AV19*参数!$B$41-AW19*参数!$B$14),0),0) -> 0 | AZ19: =AY19-MAX(AP19,0)*参数!$B$10 -> -3 | BA19: =IF(MAX(AP19,0)=0,AY19,AY19/MAX(AP19,0)) -> 0
A20: 19 | B20: ironclad_cascade | C20: 铁甲战士 | D20: 倾泻 | E20: Cascade | F20: 技能 | G20: 稀有 | H20: X | I20: X | J20: 打出你抽牌堆顶部的X张牌。 | L20: enemy_single | M20: 0 | N20: 0 | O20: 1 | P20: 0 | Q20: 0 | R20: 0 | S20: 0 | T20: 0 | U20: 0 | V20: 0 | W20: 0 | X20: 0 | Y20: 0 | Z20: 0 | AA20: 0 | AB20: 0 | AC20: 0 | AD20: 0 | AE20: 0 | AF20: 0 | AG20: 0 | AH20: 0 | AI20: 0 | AJ20: 0 | AK20: none | AP20: =IF(ISNUMBER(H20),IF(AND(H20=0,V20=0,AK20="none"),0.4,IF(AK20="exhaust",MAX(H20-V20,0.4),IF(AK20="ethereal",MAX(H20-V20,0.4),MAX(H20-V20,0.4)))),IF(AND(AK20="exhaust",OR(H20="X",H20="∞")),0.4,IF(OR(H20="X",H20="∞"),0.4,0.4))) -> 0.4 | AQ20: =参数!$B$26*参数!$B$48 -> 28 | AR20: 0 | AT20: v0.110.1 sts2.info | AU20: 0 | AY20: =IFERROR(MAX(IF(IF(AND(F20="能力",AL20="能力持续"),(参数!$B$2-1)*参数!$B$3,0)+M20*O20*参数!$B$5*IF(AND(F20="能力",AL20="能力持续"),参数!$B$2,1)+P20*参数!$B$6*IF(AND(F20="能力",AL20="能力持续"),参数!$B$2,1)+R20*参数!$B$7*IF(AND(F20="能力",AL20="能力持续"),参数!$B$2,1)+V20*参数!$B$8+IF(X20<0,X20*参数!$B$13,X20*参数!$B$39)+IF(AE20<0,AE20*参数!$B$13,AE20*参数!$B$12)*参数!$B$2+AQ20*参数!$B$15+AB20*参数!$B$11+AF20*参数!$B$40*参数!$B$2+AG20*参数!$B$44*参数!$B$2+AH20*参数!$B$6*参数!$B$2+AI20*参数!$B$39*参数!$B$2+AJ20*参数!$B$6*参数!$B$2+Z20*参数!$B$13-T20*参数!$B$14-AD20*参数!$B$13+IF(ISNUMBER(AU20),AU20*参数!$B$38,0)-AV20*参数!$B$41-AW20*参数!$B$14>参数!$B$17,参数!$B$17+SQRT(IF(AND(F20="能力",AL20="能力持续"),(参数!$B$2-1)*参数!$B$3,0)+M20*O20*参数!$B$5*IF(AND(F20="能力",AL20="能力持续"),参数!$B$2,1)+P20*参数!$B$6*IF(AND(F20="能力",AL20="能力持续"),参数!$B$2,1)+R20*参数!$B$7*IF(AND(F20="能力",AL20="能力持续"),参数!$B$2,1)+V20*参数!$B$8+IF(X20<0,X20*参数!$B$13,X20*参数!$B$39)+IF(AE20<0,AE20*参数!$B$13,AE20*参数!$B$12)*参数!$B$2+AQ20*参数!$B$15+AB20*参数!$B$11+AF20*参数!$B$40*参数!$B$2+AG20*参数!$B$44*参数!$B$2+AH20*参数!$B$6*参数!$B$2+AI20*参数!$B$39*参数!$B$2+AJ20*参数!$B$6*参数!$B$2+Z20*参数!$B$13-T20*参数!$B$14-AD20*参数!$B$13+IF(ISNUMBER(AU20),AU20*参数!$B$38,0)-AV20*参数!$B$41-AW20*参数!$B$14-参数!$B$17)*参数!$B$18,IF(AND(F20="能力",AL20="能力持续"),(参数!$B$2-1)*参数!$B$3,0)+M20*O20*参数!$B$5*IF(AND(F20="能力",AL20="能力持续"),参数!$B$2,1)+P20*参数!$B$6*IF(AND(F20="能力",AL20="能力持续"),参数!$B$2,1)+R20*参数!$B$7*IF(AND(F20="能力",AL20="能力持续"),参数!$B$2,1)+V20*参数!$B$8+IF(X20<0,X20*参数!$B$13,X20*参数!$B$39)+IF(AE20<0,AE20*参数!$B$13,AE20*参数!$B$12)*参数!$B$2+AQ20*参数!$B$15+AB20*参数!$B$11+AF20*参数!$B$40*参数!$B$2+AG20*参数!$B$44*参数!$B$2+AH20*参数!$B$6*参数!$B$2+AI20*参数!$B$39*参数!$B$2+AJ20*参数!$B$6*参数!$B$2+Z20*参数!$B$13-T20*参数!$B$14-AD20*参数!$B$13+IF(ISNUMBER(AU20),AU20*参数!$B$38,0)-AV20*参数!$B$41-AW20*参数!$B$14),0),0) -> 22.903488 | AZ20: =AY20-MAX(AP20,0)*参数!$B$10 -> 21.703488 | BA20: =IF(MAX(AP20,0)=0,AY20,AY20/MAX(AP20,0)) -> 57.25872
A21: 20 | B21: ironclad_cinder | C21: 铁甲战士 | D21: 余烬 | E21: Cinder | F21: 攻击 | G21: 普通 | H21: 2 | I21: 2 | J21: 造成18点伤害。 随机消耗1张牌。 | K21: 含消耗其他牌效果 | L21: enemy_single | M21: 18 | N21: 24 | O21: 1 | P21: 0 | Q21: 0 | R21: 0 | S21: 0 | T21: 0 | U21: 0 | V21: 0 | W21: 0 | X21: 0 | Y21: 0 | Z21: 0 | AA21: 0 | AB21: 0 | AC21: 0 | AD21: 0 | AE21: 0 | AF21: 0 | AG21: 0 | AH21: 0 | AI21: 0 | AJ21: 0 | AK21: none | AO21: 含消耗其他牌效果 | AP21: =IF(ISNUMBER(H21),IF(AND(H21=0,V21=0,AK21="none"),0.4,IF(AK21="exhaust",MAX(H21-V21,0.4),IF(AK21="ethereal",MAX(H21-V21,0.4),MAX(H21-V21,0.4)))),IF(AND(AK21="exhaust",OR(H21="X",H21="∞")),0.4,IF(OR(H21="X",H21="∞"),0.4,0.4))) -> 2 | AQ21: 0 | AR21: 0 | AT21: v0.110.1 sts2.info | AU21: 0 | AY21: =IFERROR(MAX(IF(IF(AND(F21="能力",AL21="能力持续"),(参数!$B$2-1)*参数!$B$3,0)+M21*O21*参数!$B$5*IF(AND(F21="能力",AL21="能力持续"),参数!$B$2,1)+P21*参数!$B$6*IF(AND(F21="能力",AL21="能力持续"),参数!$B$2,1)+R21*参数!$B$7*IF(AND(F21="能力",AL21="能力持续"),参数!$B$2,1)+V21*参数!$B$8+IF(X21<0,X21*参数!$B$13,X21*参数!$B$39)+IF(AE21<0,AE21*参数!$B$13,AE21*参数!$B$12)*参数!$B$2+AQ21*参数!$B$15+AB21*参数!$B$11+AF21*参数!$B$40*参数!$B$2+AG21*参数!$B$44*参数!$B$2+AH21*参数!$B$6*参数!$B$2+AI21*参数!$B$39*参数!$B$2+AJ21*参数!$B$6*参数!$B$2+Z21*参数!$B$13-T21*参数!$B$14-AD21*参数!$B$13+IF(ISNUMBER(AU21),AU21*参数!$B$38,0)-AV21*参数!$B$41-AW21*参数!$B$14>参数!$B$17,参数!$B$17+SQRT(IF(AND(F21="能力",AL21="能力持续"),(参数!$B$2-1)*参数!$B$3,0)+M21*O21*参数!$B$5*IF(AND(F21="能力",AL21="能力持续"),参数!$B$2,1)+P21*参数!$B$6*IF(AND(F21="能力",AL21="能力持续"),参数!$B$2,1)+R21*参数!$B$7*IF(AND(F21="能力",AL21="能力持续"),参数!$B$2,1)+V21*参数!$B$8+IF(X21<0,X21*参数!$B$13,X21*参数!$B$39)+IF(AE21<0,AE21*参数!$B$13,AE21*参数!$B$12)*参数!$B$2+AQ21*参数!$B$15+AB21*参数!$B$11+AF21*参数!$B$40*参数!$B$2+AG21*参数!$B$44*参数!$B$2+AH21*参数!$B$6*参数!$B$2+AI21*参数!$B$39*参数!$B$2+AJ21*参数!$B$6*参数!$B$2+Z21*参数!$B$13-T21*参数!$B$14-AD21*参数!$B$13+IF(ISNUMBER(AU21),AU21*参数!$B$38,0)-AV21*参数!$B$41-AW21*参数!$B$14-参数!$B$17)*参数!$B$18,IF(AND(F21="能力",AL21="能力持续"),(参数!$B$2-1)*参数!$B$3,0)+M21*O21*参数!$B$5*IF(AND(F21="能力",AL21="能力持续"),参数!$B$2,1)+P21*参数!$B$6*IF(AND(F21="能力",AL21="能力持续"),参数!$B$2,1)+R21*参数!$B$7*IF(AND(F21="能力",AL21="能力持续"),参数!$B$2,1)+V21*参数!$B$8+IF(X21<0,X21*参数!$B$13,X21*参数!$B$39)+IF(AE21<0,AE21*参数!$B$13,AE21*参数!$B$12)*参数!$B$2+AQ21*参数!$B$15+AB21*参数!$B$11+AF21*参数!$B$40*参数!$B$2+AG21*参数!$B$44*参数!$B$2+AH21*参数!$B$6*参数!$B$2+AI21*参数!$B$39*参数!$B$2+AJ21*参数!$B$6*参数!$B$2+Z21*参数!$B$13-T21*参数!$B$14-AD21*参数!$B$13+IF(ISNUMBER(AU21),AU21*参数!$B$38,0)-AV21*参数!$B$41-AW21*参数!$B$14),0),0) -> 14.242641 | AZ21: =AY21-MAX(AP21,0)*参数!$B$10 -> 8.2426407 | BA21: =IF(MAX(AP21,0)=0,AY21,AY21/MAX(AP21,0)) -> 7.1213203
A22: 21 | B22: ironclad_colossus | C22: 铁甲战士 | D22: 巨像 | E22: Colossus | F22: 技能 | G22: 稀有 | H22: 1 | I22: 1 | J22: 获得5点格挡。 在本回合中，有易伤状态的敌人对你造成的伤害降低50%。 | L22: self | M22: 0 | N22: 0 | O22: 1 | P22: 5 | Q22: 8 | R22: 0 | S22: 0 | T22: 0 | U22: 0 | V22: 0 | W22: 0 | X22: 0 | Y22: 0 | Z22: 0 | AA22: 0 | AB22: 0 | AC22: 0 | AD22: 0 | AE22: 0 | AF22: 0 | AG22: 0 | AH22: 0 | AI22: 0 | AJ22: 0 | AK22: none | AN22: 本回合 | AP22: =IF(ISNUMBER(H22),IF(AND(H22=0,V22=0,AK22="none"),0.4,IF(AK22="exhaust",MAX(H22-V22,0.4),IF(AK22="ethereal",MAX(H22-V22,0.4),MAX(H22-V22,0.4)))),IF(AND(AK22="exhaust",OR(H22="X",H22="∞")),0.4,IF(OR(H22="X",H22="∞"),0.4,0.4))) -> 1 | AQ22: 0 | AR22: 0 | AT22: v0.110.1 sts2.info | AU22: 0 | AY22: =IFERROR(MAX(IF(IF(AND(F22="能力",AL22="能力持续"),(参数!$B$2-1)*参数!$B$3,0)+M22*O22*参数!$B$5*IF(AND(F22="能力",AL22="能力持续"),参数!$B$2,1)+P22*参数!$B$6*IF(AND(F22="能力",AL22="能力持续"),参数!$B$2,1)+R22*参数!$B$7*IF(AND(F22="能力",AL22="能力持续"),参数!$B$2,1)+V22*参数!$B$8+IF(X22<0,X22*参数!$B$13,X22*参数!$B$39)+IF(AE22<0,AE22*参数!$B$13,AE22*参数!$B$12)*参数!$B$2+AQ22*参数!$B$15+AB22*参数!$B$11+AF22*参数!$B$40*参数!$B$2+AG22*参数!$B$44*参数!$B$2+AH22*参数!$B$6*参数!$B$2+AI22*参数!$B$39*参数!$B$2+AJ22*参数!$B$6*参数!$B$2+Z22*参数!$B$13-T22*参数!$B$14-AD22*参数!$B$13+IF(ISNUMBER(AU22),AU22*参数!$B$38,0)-AV22*参数!$B$41-AW22*参数!$B$14>参数!$B$17,参数!$B$17+SQRT(IF(AND(F22="能力",AL22="能力持续"),(参数!$B$2-1)*参数!$B$3,0)+M22*O22*参数!$B$5*IF(AND(F22="能力",AL22="能力持续"),参数!$B$2,1)+P22*参数!$B$6*IF(AND(F22="能力",AL22="能力持续"),参数!$B$2,1)+R22*参数!$B$7*IF(AND(F22="能力",AL22="能力持续"),参数!$B$2,1)+V22*参数!$B$8+IF(X22<0,X22*参数!$B$13,X22*参数!$B$39)+IF(AE22<0,AE22*参数!$B$13,AE22*参数!$B$12)*参数!$B$2+AQ22*参数!$B$15+AB22*参数!$B$11+AF22*参数!$B$40*参数!$B$2+AG22*参数!$B$44*参数!$B$2+AH22*参数!$B$6*参数!$B$2+AI22*参数!$B$39*参数!$B$2+AJ22*参数!$B$6*参数!$B$2+Z22*参数!$B$13-T22*参数!$B$14-AD22*参数!$B$13+IF(ISNUMBER(AU22),AU22*参数!$B$38,0)-AV22*参数!$B$41-AW22*参数!$B$14-参数!$B$17)*参数!$B$18,IF(AND(F22="能力",AL22="能力持续"),(参数!$B$2-1)*参数!$B$3,0)+M22*O22*参数!$B$5*IF(AND(F22="能力",AL22="能力持续"),参数!$B$2,1)+P22*参数!$B$6*IF(AND(F22="能力",AL22="能力持续"),参数!$B$2,1)+R22*参数!$B$7*IF(AND(F22="能力",AL22="能力持续"),参数!$B$2,1)+V22*参数!$B$8+IF(X22<0,X22*参数!$B$13,X22*参数!$B$39)+IF(AE22<0,AE22*参数!$B$13,AE22*参数!$B$12)*参数!$B$2+AQ22*参数!$B$15+AB22*参数!$B$11+AF22*参数!$B$40*参数!$B$2+AG22*参数!$B$44*参数!$B$2+AH22*参数!$B$6*参数!$B$2+AI22*参数!$B$39*参数!$B$2+AJ22*参数!$B$6*参数!$B$2+Z22*参数!$B$13-T22*参数!$B$14-AD22*参数!$B$13+IF(ISNUMBER(AU22),AU22*参数!$B$38,0)-AV22*参数!$B$41-AW22*参数!$B$14),0),0) -> 5.5 | AZ22: =AY22-MAX(AP22,0)*参数!$B$10 -> 2.5 | BA22: =IF(MAX(AP22,0)=0,AY22,AY22/MAX(AP22,0)) -> 5.5
A23: 22 | B23: ironclad_conflagration | C23: 铁甲战士 | D23: 恶魔之焰 | E23: Conflagration | F23: 攻击 | G23: 稀有 | H23: 1 | I23: 1 | J23: 消耗所有手牌。 每张被消耗的牌造成7点伤害。 | L23: enemy_all | M23: 7 | N23: 10 | O23: 5 | P23: 0 | Q23: 0 | R23: 0 | S23: 0 | T23: 0 | U23: 0 | V23: 0 | W23: 0 | X23: 0 | Y23: 0 | Z23: 0 | AA23: 0 | AB23: 0 | AC23: 0 | AD23: 0 | AE23: 0 | AF23: 0 | AG23: 0 | AH23: 0 | AI23: 0 | AJ23: 0 | AK23: none | AN23: 群体攻击，本回合 | AP23: =IF(ISNUMBER(H23),IF(AND(H23=0,V23=0,AK23="none"),0.4,IF(AK23="exhaust",MAX(H23-V23,0.4),IF(AK23="ethereal",MAX(H23-V23,0.4),MAX(H23-V23,0.4)))),IF(AND(AK23="exhaust",OR(H23="X",H23="∞")),0.4,IF(OR(H23="X",H23="∞"),0.4,0.4))) -> 1 | AQ23: 0 | AR23: 0 | AT23: v0.110.1 sts2.info | AU23: 0 | AY23: =IFERROR(MAX(IF(IF(AND(F23="能力",AL23="能力持续"),(参数!$B$2-1)*参数!$B$3,0)+M23*O23*参数!$B$5*IF(AND(F23="能力",AL23="能力持续"),参数!$B$2,1)+P23*参数!$B$6*IF(AND(F23="能力",AL23="能力持续"),参数!$B$2,1)+R23*参数!$B$7*IF(AND(F23="能力",AL23="能力持续"),参数!$B$2,1)+V23*参数!$B$8+IF(X23<0,X23*参数!$B$13,X23*参数!$B$39)+IF(AE23<0,AE23*参数!$B$13,AE23*参数!$B$12)*参数!$B$2+AQ23*参数!$B$15+AB23*参数!$B$11+AF23*参数!$B$40*参数!$B$2+AG23*参数!$B$44*参数!$B$2+AH23*参数!$B$6*参数!$B$2+AI23*参数!$B$39*参数!$B$2+AJ23*参数!$B$6*参数!$B$2+Z23*参数!$B$13-T23*参数!$B$14-AD23*参数!$B$13+IF(ISNUMBER(AU23),AU23*参数!$B$38,0)-AV23*参数!$B$41-AW23*参数!$B$14>参数!$B$17,参数!$B$17+SQRT(IF(AND(F23="能力",AL23="能力持续"),(参数!$B$2-1)*参数!$B$3,0)+M23*O23*参数!$B$5*IF(AND(F23="能力",AL23="能力持续"),参数!$B$2,1)+P23*参数!$B$6*IF(AND(F23="能力",AL23="能力持续"),参数!$B$2,1)+R23*参数!$B$7*IF(AND(F23="能力",AL23="能力持续"),参数!$B$2,1)+V23*参数!$B$8+IF(X23<0,X23*参数!$B$13,X23*参数!$B$39)+IF(AE23<0,AE23*参数!$B$13,AE23*参数!$B$12)*参数!$B$2+AQ23*参数!$B$15+AB23*参数!$B$11+AF23*参数!$B$40*参数!$B$2+AG23*参数!$B$44*参数!$B$2+AH23*参数!$B$6*参数!$B$2+AI23*参数!$B$39*参数!$B$2+AJ23*参数!$B$6*参数!$B$2+Z23*参数!$B$13-T23*参数!$B$14-AD23*参数!$B$13+IF(ISNUMBER(AU23),AU23*参数!$B$38,0)-AV23*参数!$B$41-AW23*参数!$B$14-参数!$B$17)*参数!$B$18,IF(AND(F23="能力",AL23="能力持续"),(参数!$B$2-1)*参数!$B$3,0)+M23*O23*参数!$B$5*IF(AND(F23="能力",AL23="能力持续"),参数!$B$2,1)+P23*参数!$B$6*IF(AND(F23="能力",AL23="能力持续"),参数!$B$2,1)+R23*参数!$B$7*IF(AND(F23="能力",AL23="能力持续"),参数!$B$2,1)+V23*参数!$B$8+IF(X23<0,X23*参数!$B$13,X23*参数!$B$39)+IF(AE23<0,AE23*参数!$B$13,AE23*参数!$B$12)*参数!$B$2+AQ23*参数!$B$15+AB23*参数!$B$11+AF23*参数!$B$40*参数!$B$2+AG23*参数!$B$44*参数!$B$2+AH23*参数!$B$6*参数!$B$2+AI23*参数!$B$39*参数!$B$2+AJ23*参数!$B$6*参数!$B$2+Z23*参数!$B$13-T23*参数!$B$14-AD23*参数!$B$13+IF(ISNUMBER(AU23),AU23*参数!$B$38,0)-AV23*参数!$B$41-AW23*参数!$B$14),0),0) -> 17.5 | AZ23: =AY23-MAX(AP23,0)*参数!$B$10 -> 14.5 | BA23: =IF(MAX(AP23,0)=0,AY23,AY23/MAX(AP23,0)) -> 17.5
A24: 23 | B24: ironclad_corruption | C24: 铁甲战士 | D24: 腐化 | E24: Corruption | F24: 能力 | G24: 远古 | H24: 3 | I24: 2 | J24: 技能牌消耗变为0Energy。 每当你打出一张技能牌时，将其消耗。 | K24: 含消耗其他牌效果 | L24: self | M24: 0 | N24: 0 | O24: 1 | P24: 0 | Q24: 0 | R24: 0 | S24: 0 | T24: 0 | U24: 0 | V24: 0 | W24: 0 | X24: 0 | Y24: 0 | Z24: 0 | AA24: 0 | AB24: 0 | AC24: 0 | AD24: 0 | AE24: 0 | AF24: 0 | AG24: 0 | AH24: 0 | AI24: 0 | AJ24: 0 | AK24: none | AL24: 能力持续 | AN24: 能力 | AO24: 含消耗其他牌效果 | AP24: =IF(ISNUMBER(H24),IF(AND(H24=0,V24=0,AK24="none"),0.4,IF(AK24="exhaust",MAX(H24-V24,0.4),IF(AK24="ethereal",MAX(H24-V24,0.4),MAX(H24-V24,0.4)))),IF(AND(AK24="exhaust",OR(H24="X",H24="∞")),0.4,IF(OR(H24="X",H24="∞"),0.4,0.4))) -> 3 | AQ24: 0 | AR24: 0 | AT24: v0.110.1 sts2.info | AU24: 0 | AY24: =IFERROR(MAX(IF(IF(AND(F24="能力",AL24="能力持续"),(参数!$B$2-1)*参数!$B$3,0)+M24*O24*参数!$B$5*IF(AND(F24="能力",AL24="能力持续"),参数!$B$2,1)+P24*参数!$B$6*IF(AND(F24="能力",AL24="能力持续"),参数!$B$2,1)+R24*参数!$B$7*IF(AND(F24="能力",AL24="能力持续"),参数!$B$2,1)+V24*参数!$B$8+IF(X24<0,X24*参数!$B$13,X24*参数!$B$39)+IF(AE24<0,AE24*参数!$B$13,AE24*参数!$B$12)*参数!$B$2+AQ24*参数!$B$15+AB24*参数!$B$11+AF24*参数!$B$40*参数!$B$2+AG24*参数!$B$44*参数!$B$2+AH24*参数!$B$6*参数!$B$2+AI24*参数!$B$39*参数!$B$2+AJ24*参数!$B$6*参数!$B$2+Z24*参数!$B$13-T24*参数!$B$14-AD24*参数!$B$13+IF(ISNUMBER(AU24),AU24*参数!$B$38,0)-AV24*参数!$B$41-AW24*参数!$B$14>参数!$B$17,参数!$B$17+SQRT(IF(AND(F24="能力",AL24="能力持续"),(参数!$B$2-1)*参数!$B$3,0)+M24*O24*参数!$B$5*IF(AND(F24="能力",AL24="能力持续"),参数!$B$2,1)+P24*参数!$B$6*IF(AND(F24="能力",AL24="能力持续"),参数!$B$2,1)+R24*参数!$B$7*IF(AND(F24="能力",AL24="能力持续"),参数!$B$2,1)+V24*参数!$B$8+IF(X24<0,X24*参数!$B$13,X24*参数!$B$39)+IF(AE24<0,AE24*参数!$B$13,AE24*参数!$B$12)*参数!$B$2+AQ24*参数!$B$15+AB24*参数!$B$11+AF24*参数!$B$40*参数!$B$2+AG24*参数!$B$44*参数!$B$2+AH24*参数!$B$6*参数!$B$2+AI24*参数!$B$39*参数!$B$2+AJ24*参数!$B$6*参数!$B$2+Z24*参数!$B$13-T24*参数!$B$14-AD24*参数!$B$13+IF(ISNUMBER(AU24),AU24*参数!$B$38,0)-AV24*参数!$B$41-AW24*参数!$B$14-参数!$B$17)*参数!$B$18,IF(AND(F24="能力",AL24="能力持续"),(参数!$B$2-1)*参数!$B$3,0)+M24*O24*参数!$B$5*IF(AND(F24="能力",AL24="能力持续"),参数!$B$2,1)+P24*参数!$B$6*IF(AND(F24="能力",AL24="能力持续"),参数!$B$2,1)+R24*参数!$B$7*IF(AND(F24="能力",AL24="能力持续"),参数!$B$2,1)+V24*参数!$B$8+IF(X24<0,X24*参数!$B$13,X24*参数!$B$39)+IF(AE24<0,AE24*参数!$B$13,AE24*参数!$B$12)*参数!$B$2+AQ24*参数!$B$15+AB24*参数!$B$11+AF24*参数!$B$40*参数!$B$2+AG24*参数!$B$44*参数!$B$2+AH24*参数!$B$6*参数!$B$2+AI24*参数!$B$39*参数!$B$2+AJ24*参数!$B$6*参数!$B$2+Z24*参数!$B$13-T24*参数!$B$14-AD24*参数!$B$13+IF(ISNUMBER(AU24),AU24*参数!$B$38,0)-AV24*参数!$B$41-AW24*参数!$B$14),0),0) -> 3.6 | AZ24: =AY24-MAX(AP24,0)*参数!$B$10 -> -5.4 | BA24: =IF(MAX(AP24,0)=0,AY24,AY24/MAX(AP24,0)) -> 1.2
